Workbook

Sheet Start Here
B10: Day 4: Advanced Logical Engines
B12: Build 'Spreadsheet Brains'. Master IF, IFS, AND, OR, and SWITCH logic for complex decision making.

Sheet Logic_Data
A1: User ID | B1: Score | C1: Region | D1: Active
A2: USR-501 | B2: 86 | C2: South | D2: TRUE
A3: USR-502 | B3: 92 | C3: South | D3: TRUE
A4: USR-503 | B4: 26 | C4: South | D4: FALSE
A5: USR-504 | B5: 24 | C5: West | D5: TRUE
A6: USR-505 | B6: 1 | C6: East | D6: FALSE
A7: USR-506 | B7: 82 | C7: North | D7: TRUE
A8: USR-507 | B8: 83 | C8: East | D8: TRUE
A9: USR-508 | B9: 100 | C9: West | D9: FALSE
A10: USR-509 | B10: 45 | C10: West | D10: FALSE
A11: USR-510 | B11: 39 | C11: West | D11: TRUE
A12: USR-511 | B12: 36 | C12: West | D12: TRUE
A13: USR-512 | B13: 100 | C13: West | D13: FALSE
... A101: USR-600 | B101: 51 | C101: East | D101: FALSE

Sheet The_Archive
A1: Task # | B1: Expected Result
A2: 1 | B2: =IF(Logic_Data!B2>70,"Pass","Fail")
A3: 2 | B3: =IFS(Logic_Data!B2>90,"A",Logic_Data!B2>80,"B",TRUE,"C")
A4: 3 | B4: =IF(AND(Logic_Data!C2="North",Logic_Data!B2>50),"Bonus","None")
A5: 4 | B5: =IF(Logic_Data!B5>50,"Good","Bad")
A6: 5 | B6: =IF(Logic_Data!B6>50,"Good","Bad")
A7: 6 | B7: =IF(Logic_Data!B7>50,"Good","Bad")
A8: 7 | B8: =IF(Logic_Data!B8>50,"Good","Bad")
A9: 8 | B9: =IF(Logic_Data!B9>50,"Good","Bad")
A10: 9 | B10: =IF(Logic_Data!B10>50,"Good","Bad")
A11: 10 | B11: =IF(Logic_Data!B11>50,"Good","Bad")
A12: 11 | B12: =IF(Logic_Data!B12>50,"Good","Bad")
A13: 12 | B13: =IF(Logic_Data!B13>50,"Good","Bad")
A14: 13 | B14: =IF(Logic_Data!B14>50,"Good","Bad")
A15: 14 | B15: =IF(Logic_Data!B15>50,"Good","Bad")
A16: 15 | B16: =IF(Logic_Data!B16>50,"Good","Bad")
... A41: 40 | B41: =IF(Logic_Data!B41>50,"Good","Bad")

Sheet Mastery_Lab
B2: LOGICAL FUNCTIONS DRILL
B6: 1. If Score > 70, return 'Pass', else 'Fail' (Score in Logic_Data!B2) | D6: =IF(C6="","[ Pending ]", IF(C6=The_Archive!B2, "✅ Correct", "❌ Try Again"))
B8: 2. If Score > 90 'A', > 80 'B', else 'C' (Use IFS) | D8: =IF(C8="","[ Pending ]", IF(C8=The_Archive!B3, "✅ Correct", "❌ Try Again"))
B10: 3. If Region is 'North' AND Score > 50, 'Bonus', else 'None' | D10: =IF(C10="","[ Pending ]", IF(C10=The_Archive!B4, "✅ Correct", "❌ Try Again"))
B12: 4. Additional Task 4: Logic check for USR-504 | D12: =IF(C12="","[ Pending ]", IF(C12=The_Archive!B5, "✅ Correct", "❌ Try Again"))
B14: 5. Additional Task 5: Logic check for USR-505 | D14: =IF(C14="","[ Pending ]", IF(C14=The_Archive!B6, "✅ Correct", "❌ Try Again"))
B16: 6. Additional Task 6: Logic check for USR-506 | D16: =IF(C16="","[ Pending ]", IF(C16=The_Archive!B7, "✅ Correct", "❌ Try Again"))
B18: 7. Additional Task 7: Logic check for USR-507 | D18: =IF(C18="","[ Pending ]", IF(C18=The_Archive!B8, "✅ Correct", "❌ Try Again"))
B20: 8. Additional Task 8: Logic check for USR-508 | D20: =IF(C20="","[ Pending ]", IF(C20=The_Archive!B9, "✅ Correct", "❌ Try Again"))
B22: 9. Additional Task 9: Logic check for USR-509 | D22: =IF(C22="","[ Pending ]", IF(C22=The_Archive!B10, "✅ Correct", "❌ Try Again"))
B24: 10. Additional Task 10: Logic check for USR-510 | D24: =IF(C24="","[ Pending ]", IF(C24=The_Archive!B11, "✅ Correct", "❌ Try Again"))
B26: 11. Additional Task 11: Logic check for USR-511 | D26: =IF(C26="","[ Pending ]", IF(C26=The_Archive!B12, "✅ Correct", "❌ Try Again"))
B28: 12. Additional Task 12: Logic check for USR-512 | D28: =IF(C28="","[ Pending ]", IF(C28=The_Archive!B13, "✅ Correct", "❌ Try Again"))
B30: 13. Additional Task 13: Logic check for USR-513 | D30: =IF(C30="","[ Pending ]", IF(C30=The_Archive!B14, "✅ Correct", "❌ Try Again"))
B32: 14. Additional Task 14: Logic check for USR-514 | D32: =IF(C32="","[ Pending ]", IF(C32=The_Archive!B15, "✅ Correct", "❌ Try Again"))
B34: 15. Additional Task 15: Logic check for USR-515 | D34: =IF(C34="","[ Pending ]", IF(C34=The_Archive!B16, "✅ Correct", "❌ Try Again"))
B36: 16. Additional Task 16: Logic check for USR-516 | D36: =IF(C36="","[ Pending ]", IF(C36=The_Archive!B17, "✅ Correct", "❌ Try Again"))
B38: 17. Additional Task 17: Logic check for USR-517 | D38: =IF(C38="","[ Pending ]", IF(C38=The_Archive!B18, "✅ Correct", "❌ Try Again"))
B40: 18. Additional Task 18: Logic check for USR-518 | D40: =IF(C40="","[ Pending ]", IF(C40=The_Archive!B19, "✅ Correct", "❌ Try Again"))
B42: 19. Additional Task 19: Logic check for USR-519 | D42: =IF(C42="","[ Pending ]", IF(C42=The_Archive!B20, "✅ Correct", "❌ Try Again"))
B44: 20. Additional Task 20: Logic check for USR-520 | D44: =IF(C44="","[ Pending ]", IF(C44=The_Archive!B21, "✅ Correct", "❌ Try Again"))
B46: 21. Additional Task 21: Logic check for USR-521 | D46: =IF(C46="","[ Pending ]", IF(C46=The_Archive!B22, "✅ Correct", "❌ Try Again"))
B48: 22. Additional Task 22: Logic check for USR-522 | D48: =IF(C48="","[ Pending ]", IF(C48=The_Archive!B23, "✅ Correct", "❌ Try Again"))
B50: 23. Additional Task 23: Logic check for USR-523 | D50: =IF(C50="","[ Pending ]", IF(C50=The_Archive!B24, "✅ Correct", "❌ Try Again"))
B52: 24. Additional Task 24: Logic check for USR-524 | D52: =IF(C52="","[ Pending ]", IF(C52=The_Archive!B25, "✅ Correct", "❌ Try Again"))
B54: 25. Additional Task 25: Logic check for USR-525 | D54: =IF(C54="","[ Pending ]", IF(C54=The_Archive!B26, "✅ Correct", "❌ Try Again"))
B56: 26. Additional Task 26: Logic check for USR-526 | D56: =IF(C56="","[ Pending ]", IF(C56=The_Archive!B27, "✅ Correct", "❌ Try Again"))
B58: 27. Additional Task 27: Logic check for USR-527 | D58: =IF(C58="","[ Pending ]", IF(C58=The_Archive!B28, "✅ Correct", "❌ Try Again"))
B60: 28. Additional Task 28: Logic check for USR-528 | D60: =IF(C60="","[ Pending ]", IF(C60=The_Archive!B29, "✅ Correct", "❌ Try Again"))
B62: 29. Additional Task 29: Logic check for USR-529 | D62: =IF(C62="","[ Pending ]", IF(C62=The_Archive!B30, "✅ Correct", "❌ Try Again"))
B64: 30. Additional Task 30: Logic check for USR-530 | D64: =IF(C64="","[ Pending ]", IF(C64=The_Archive!B31, "✅ Correct", "❌ Try Again"))
B66: 31. Additional Task 31: Logic check for USR-531 | D66: =IF(C66="","[ Pending ]", IF(C66=The_Archive!B32, "✅ Correct", "❌ Try Again"))
B68: 32. Additional Task 32: Logic check for USR-532 | D68: =IF(C68="","[ Pending ]", IF(C68=The_Archive!B33, "✅ Correct", "❌ Try Again"))
B70: 33. Additional Task 33: Logic check for USR-533 | D70: =IF(C70="","[ Pending ]", IF(C70=The_Archive!B34, "✅ Correct", "❌ Try Again"))
B72: 34. Additional Task 34: Logic check for USR-534 | D72: =IF(C72="","[ Pending ]", IF(C72=The_Archive!B35, "✅ Correct", "❌ Try Again"))
B74: 35. Additional Task 35: Logic check for USR-535 | D74: =IF(C74="","[ Pending ]", IF(C74=The_Archive!B36, "✅ Correct", "❌ Try Again"))
B76: 36. Additional Task 36: Logic check for USR-536 | D76: =IF(C76="","[ Pending ]", IF(C76=The_Archive!B37, "✅ Correct", "❌ Try Again"))
B78: 37. Additional Task 37: Logic check for USR-537 | D78: =IF(C78="","[ Pending ]", IF(C78=The_Archive!B38, "✅ Correct", "❌ Try Again"))
B80: 38. Additional Task 38: Logic check for USR-538 | D80: =IF(C80="","[ Pending ]", IF(C80=The_Archive!B39, "✅ Correct", "❌ Try Again"))
B82: 39. Additional Task 39: Logic check for USR-539 | D82: =IF(C82="","[ Pending ]", IF(C82=The_Archive!B40, "✅ Correct", "❌ Try Again"))
...
