Workbook

Sheet Start Here
B10: Day 2: XLOOKUP & Lookup Architecture
B12: Master the art of dynamic data retrieval. Stop using legacy VLOOKUP and build resilient search engines.

Sheet Master_Data
A1: SKU | B1: Product | C1: Category | D1: Price | E1: Stock
A2: SKU-1001 | B2: Lamp v1 | C2: Electronics | D2: 1743 | E2: 194
A3: SKU-1002 | B3: Laptop v2 | C3: Electronics | D3: 1413 | E3: 360
A4: SKU-1003 | B4: SSD v3 | C4: Electronics | D4: 1420 | E4: 123
A5: SKU-1004 | B5: Monitor v4 | C5: Electronics | D5: 938 | E5: 95
A6: SKU-1005 | B6: Webcam v5 | C6: Electronics | D6: 1977 | E6: 350
A7: SKU-1006 | B7: Keyboard v6 | C7: Electronics | D7: 1420 | E7: 442
A8: SKU-1007 | B8: Desk v7 | C8: Electronics | D8: 704 | E8: 281
A9: SKU-1008 | B9: Laptop v8 | C9: Electronics | D9: 137 | E9: 9
A10: SKU-1009 | B10: Keyboard v9 | C10: Electronics | D10: 1776 | E10: 130
A11: SKU-1010 | B11: Desk v10 | C11: Electronics | D11: 765 | E11: 16
A12: SKU-1011 | B12: Keyboard v11 | C12: Electronics | D12: 1702 | E12: 369
A13: SKU-1012 | B13: SSD v12 | C13: Electronics | D13: 79 | E13: 162
... A101: SKU-1100 | B101: Laptop v100 | C101: Electronics | D101: 1566 | E101: 376

Sheet The_Archive
A1: Task # | B1: Expected Formula / Result
A2: 1 | B2: =XLOOKUP("SKU-1001",Master_Data!A:A,Master_Data!D:D)
A3: 2 | B3: =XLOOKUP("SKU-1005",Master_Data!A:A,Master_Data!B:B)
A4: 3 | B4: =XLOOKUP("SKU-1010",Master_Data!A:A,Master_Data!E:E)
A5: 4 | B5: =XLOOKUP("SKU-9999",Master_Data!A:A,Master_Data!B:B,"Not Found")
A6: 5 | B6: =XLOOKUP("Electronics",Master_Data!C:C,Master_Data!A:A)
A7: 6 | B7: =XLOOKUP("SKU-1006",Master_Data!A:A,Master_Data!D:D)
A8: 7 | B8: =XLOOKUP("SKU-1007",Master_Data!A:A,Master_Data!D:D)
A9: 8 | B9: =XLOOKUP("SKU-1008",Master_Data!A:A,Master_Data!D:D)
A10: 9 | B10: =XLOOKUP("SKU-1009",Master_Data!A:A,Master_Data!D:D)
A11: 10 | B11: =XLOOKUP("SKU-1010",Master_Data!A:A,Master_Data!D:D)
A12: 11 | B12: =XLOOKUP("SKU-1011",Master_Data!A:A,Master_Data!D:D)
A13: 12 | B13: =XLOOKUP("SKU-1012",Master_Data!A:A,Master_Data!D:D)
A14: 13 | B14: =XLOOKUP("SKU-1013",Master_Data!A:A,Master_Data!D:D)
A15: 14 | B15: =XLOOKUP("SKU-1014",Master_Data!A:A,Master_Data!D:D)
A16: 15 | B16: =XLOOKUP("SKU-1015",Master_Data!A:A,Master_Data!D:D)
A17: 16 | B17: =XLOOKUP("SKU-1016",Master_Data!A:A,Master_Data!D:D)
A18: 17 | B18: =XLOOKUP("SKU-1017",Master_Data!A:A,Master_Data!D:D)
A19: 18 | B19: =XLOOKUP("SKU-1018",Master_Data!A:A,Master_Data!D:D)
A20: 19 | B20: =XLOOKUP("SKU-1019",Master_Data!A:A,Master_Data!D:D)
A21: 20 | B21: =XLOOKUP("SKU-1020",Master_Data!A:A,Master_Data!D:D)
A22: 21 | B22: =XLOOKUP("SKU-1021",Master_Data!A:A,Master_Data!D:D)
A23: 22 | B23: =XLOOKUP("SKU-1022",Master_Data!A:A,Master_Data!D:D)
A24: 23 | B24: =XLOOKUP("SKU-1023",Master_Data!A:A,Master_Data!D:D)
A25: 24 | B25: =XLOOKUP("SKU-1024",Master_Data!A:A,Master_Data!D:D)
A26: 25 | B26: =XLOOKUP("SKU-1025",Master_Data!A:A,Master_Data!D:D)
A27: 26 | B27: =XLOOKUP("SKU-1026",Master_Data!A:A,Master_Data!D:D)
A28: 27 | B28: =XLOOKUP("SKU-1027",Master_Data!A:A,Master_Data!D:D)
A29: 28 | B29: =XLOOKUP("SKU-1028",Master_Data!A:A,Master_Data!D:D)
A30: 29 | B30: =XLOOKUP("SKU-1029",Master_Data!A:A,Master_Data!D:D)
A31: 30 | B31: =XLOOKUP("SKU-1030",Master_Data!A:A,Master_Data!D:D)
A32: 31 | B32: =XLOOKUP("SKU-1031",Master_Data!A:A,Master_Data!D:D)
A33: 32 | B33: =XLOOKUP("SKU-1032",Master_Data!A:A,Master_Data!D:D)
A34: 33 | B34: =XLOOKUP("SKU-1033",Master_Data!A:A,Master_Data!D:D)
A35: 34 | B35: =XLOOKUP("SKU-1034",Master_Data!A:A,Master_Data!D:D)
A36: 35 | B36: =XLOOKUP("SKU-1035",Master_Data!A:A,Master_Data!D:D)
A37: 36 | B37: =XLOOKUP("SKU-1036",Master_Data!A:A,Master_Data!D:D)
A38: 37 | B38: =XLOOKUP("SKU-1037",Master_Data!A:A,Master_Data!D:D)
A39: 38 | B39: =XLOOKUP("SKU-1038",Master_Data!A:A,Master_Data!D:D)
A40: 39 | B40: =XLOOKUP("SKU-1039",Master_Data!A:A,Master_Data!D:D)
...

Sheet Mastery_Lab
B2: XLOOKUP MASTERY DRILL
B6: 1. Find the Price of SKU-1001 | D6: =IF(C6="","[ Pending ]", IF(C6=The_Archive!B2, "✅ Correct", "❌ Try Again"))
B8: 2. Find the Product Name of SKU-1005 | D8: =IF(C8="","[ Pending ]", IF(C8=The_Archive!B3, "✅ Correct", "❌ Try Again"))
B10: 3. Find the Stock Level of SKU-1010 | D10: =IF(C10="","[ Pending ]", IF(C10=The_Archive!B4, "✅ Correct", "❌ Try Again"))
B12: 4. Lookup SKU-9999 and return 'Not Found' if missing | D12: =IF(C12="","[ Pending ]", IF(C12=The_Archive!B5, "✅ Correct", "❌ Try Again"))
B14: 5. Find the first SKU for 'Electronics' | D14: =IF(C14="","[ Pending ]", IF(C14=The_Archive!B6, "✅ Correct", "❌ Try Again"))
B16: 6. Additional Task 6: Perform a lookup for SKU-1006 | D16: =IF(C16="","[ Pending ]", IF(C16=The_Archive!B7, "✅ Correct", "❌ Try Again"))
B18: 7. Additional Task 7: Perform a lookup for SKU-1007 | D18: =IF(C18="","[ Pending ]", IF(C18=The_Archive!B8, "✅ Correct", "❌ Try Again"))
B20: 8. Additional Task 8: Perform a lookup for SKU-1008 | D20: =IF(C20="","[ Pending ]", IF(C20=The_Archive!B9, "✅ Correct", "❌ Try Again"))
B22: 9. Additional Task 9: Perform a lookup for SKU-1009 | D22: =IF(C22="","[ Pending ]", IF(C22=The_Archive!B10, "✅ Correct", "❌ Try Again"))
B24: 10. Additional Task 10: Perform a lookup for SKU-1010 | D24: =IF(C24="","[ Pending ]", IF(C24=The_Archive!B11, "✅ Correct", "❌ Try Again"))
B26: 11. Additional Task 11: Perform a lookup for SKU-1011 | D26: =IF(C26="","[ Pending ]", IF(C26=The_Archive!B12, "✅ Correct", "❌ Try Again"))
B28: 12. Additional Task 12: Perform a lookup for SKU-1012 | D28: =IF(C28="","[ Pending ]", IF(C28=The_Archive!B13, "✅ Correct", "❌ Try Again"))
B30: 13. Additional Task 13: Perform a lookup for SKU-1013 | D30: =IF(C30="","[ Pending ]", IF(C30=The_Archive!B14, "✅ Correct", "❌ Try Again"))
B32: 14. Additional Task 14: Perform a lookup for SKU-1014 | D32: =IF(C32="","[ Pending ]", IF(C32=The_Archive!B15, "✅ Correct", "❌ Try Again"))
B34: 15. Additional Task 15: Perform a lookup for SKU-1015 | D34: =IF(C34="","[ Pending ]", IF(C34=The_Archive!B16, "✅ Correct", "❌ Try Again"))
B36: 16. Additional Task 16: Perform a lookup for SKU-1016 | D36: =IF(C36="","[ Pending ]", IF(C36=The_Archive!B17, "✅ Correct", "❌ Try Again"))
B38: 17. Additional Task 17: Perform a lookup for SKU-1017 | D38: =IF(C38="","[ Pending ]", IF(C38=The_Archive!B18, "✅ Correct", "❌ Try Again"))
B40: 18. Additional Task 18: Perform a lookup for SKU-1018 | D40: =IF(C40="","[ Pending ]", IF(C40=The_Archive!B19, "✅ Correct", "❌ Try Again"))
B42: 19. Additional Task 19: Perform a lookup for SKU-1019 | D42: =IF(C42="","[ Pending ]", IF(C42=The_Archive!B20, "✅ Correct", "❌ Try Again"))
B44: 20. Additional Task 20: Perform a lookup for SKU-1020 | D44: =IF(C44="","[ Pending ]", IF(C44=The_Archive!B21, "✅ Correct", "❌ Try Again"))
B46: 21. Additional Task 21: Perform a lookup for SKU-1021 | D46: =IF(C46="","[ Pending ]", IF(C46=The_Archive!B22, "✅ Correct", "❌ Try Again"))
B48: 22. Additional Task 22: Perform a lookup for SKU-1022 | D48: =IF(C48="","[ Pending ]", IF(C48=The_Archive!B23, "✅ Correct", "❌ Try Again"))
B50: 23. Additional Task 23: Perform a lookup for SKU-1023 | D50: =IF(C50="","[ Pending ]", IF(C50=The_Archive!B24, "✅ Correct", "❌ Try Again"))
B52: 24. Additional Task 24: Perform a lookup for SKU-1024 | D52: =IF(C52="","[ Pending ]", IF(C52=The_Archive!B25, "✅ Correct", "❌ Try Again"))
B54: 25. Additional Task 25: Perform a lookup for SKU-1025 | D54: =IF(C54="","[ Pending ]", IF(C54=The_Archive!B26, "✅ Correct", "❌ Try Again"))
B56: 26. Additional Task 26: Perform a lookup for SKU-1026 | D56: =IF(C56="","[ Pending ]", IF(C56=The_Archive!B27, "✅ Correct", "❌ Try Again"))
B58: 27. Additional Task 27: Perform a lookup for SKU-1027 | D58: =IF(C58="","[ Pending ]", IF(C58=The_Archive!B28, "✅ Correct", "❌ Try Again"))
B60: 28. Additional Task 28: Perform a lookup for SKU-1028 | D60: =IF(C60="","[ Pending ]", IF(C60=The_Archive!B29, "✅ Correct", "❌ Try Again"))
B62: 29. Additional Task 29: Perform a lookup for SKU-1029 | D62: =IF(C62="","[ Pending ]", IF(C62=The_Archive!B30, "✅ Correct", "❌ Try Again"))
B64: 30. Additional Task 30: Perform a lookup for SKU-1030 | D64: =IF(C64="","[ Pending ]", IF(C64=The_Archive!B31, "✅ Correct", "❌ Try Again"))
B66: 31. Additional Task 31: Perform a lookup for SKU-1031 | D66: =IF(C66="","[ Pending ]", IF(C66=The_Archive!B32, "✅ Correct", "❌ Try Again"))
B68: 32. Additional Task 32: Perform a lookup for SKU-1032 | D68: =IF(C68="","[ Pending ]", IF(C68=The_Archive!B33, "✅ Correct", "❌ Try Again"))
B70: 33. Additional Task 33: Perform a lookup for SKU-1033 | D70: =IF(C70="","[ Pending ]", IF(C70=The_Archive!B34, "✅ Correct", "❌ Try Again"))
B72: 34. Additional Task 34: Perform a lookup for SKU-1034 | D72: =IF(C72="","[ Pending ]", IF(C72=The_Archive!B35, "✅ Correct", "❌ Try Again"))
B74: 35. Additional Task 35: Perform a lookup for SKU-1035 | D74: =IF(C74="","[ Pending ]", IF(C74=The_Archive!B36, "✅ Correct", "❌ Try Again"))
B76: 36. Additional Task 36: Perform a lookup for SKU-1036 | D76: =IF(C76="","[ Pending ]", IF(C76=The_Archive!B37, "✅ Correct", "❌ Try Again"))
B78: 37. Additional Task 37: Perform a lookup for SKU-1037 | D78: =IF(C78="","[ Pending ]", IF(C78=The_Archive!B38, "✅ Correct", "❌ Try Again"))
B80: 38. Additional Task 38: Perform a lookup for SKU-1038 | D80: =IF(C80="","[ Pending ]", IF(C80=The_Archive!B39, "✅ Correct", "❌ Try Again"))
B82: 39. Additional Task 39: Perform a lookup for SKU-1039 | D82: =IF(C82="","[ Pending ]", IF(C82=The_Archive!B40, "✅ Correct", "❌ Try Again"))
...
