Workbook

Sheet Start Here
B10: Day 1: Data Cleaning Mastery
B12: Master the art of 1-click cleaning. Stop being a Data Janitor. Build automated cleaning pipelines.

Sheet Raw_Data
A1: Dirty Name | B1: Code | C1: Amount
A2: jane smith | B2: 100-X | C2: $310.00
A3: CHARLIE brown | B3: 200-X | C3: $882.00
A4: bob builder | B4: 300-X | C4: $472.00
A5: john DOE | B5: 400-X | C5: $405.00
A6: jane smith | B6: 500-X | C6: $378.00
A7: ALICE WONDER | B7: 600-X | C7: $827.00
A8: john DOE | B8: 700-X | C8: $147.00
A9: bob builder | B9: 800-X | C9: $781.00
A10: bob builder | B10: 900-X | C10: $282.00
A11: jane smith | B11: 1000-X | C11: $983.00
A12: jane smith | B12: 1100-X | C12: $821.00
... A51: CHARLIE brown | B51: 5000-X | C51: $652.00

Sheet The_Archive
A1: Task # | B1: Expected Result
A2: 1 | B2: =PROPER(TRIM(Raw_Data!A2))
A3: 2 | B3: =TRIM(Raw_Data!B2)
A4: 3 | B4: =VALUE(SUBSTITUTE(Raw_Data!C2,"$",""))
A5: 4 | B5: =PROPER(TRIM(Raw_Data!A2)) & " - " & TRIM(Raw_Data!B2)
A6: 5 | B6: =PROPER(TRIM(Raw_Data!A6))
A7: 6 | B7: =PROPER(TRIM(Raw_Data!A7))
A8: 7 | B8: =PROPER(TRIM(Raw_Data!A8))
A9: 8 | B9: =PROPER(TRIM(Raw_Data!A9))
A10: 9 | B10: =PROPER(TRIM(Raw_Data!A10))
A11: 10 | B11: =PROPER(TRIM(Raw_Data!A11))
A12: 11 | B12: =PROPER(TRIM(Raw_Data!A12))
A13: 12 | B13: =PROPER(TRIM(Raw_Data!A13))
A14: 13 | B14: =PROPER(TRIM(Raw_Data!A14))
A15: 14 | B15: =PROPER(TRIM(Raw_Data!A15))
A16: 15 | B16: =PROPER(TRIM(Raw_Data!A16))
A17: 16 | B17: =PROPER(TRIM(Raw_Data!A17))
... A41: 40 | B41: =PROPER(TRIM(Raw_Data!A41))

Sheet Mastery_Lab
B2: DATA CLEANING DRILL
B6: 1. Clean and Trim 'Dirty Name' from Raw_Data!A2 | D6: =IF(C6="","[ Pending ]", IF(C6=The_Archive!B2, "✅ Correct", "❌ Try Again"))
B8: 2. Remove spaces from 'Code' in Raw_Data!B2 | D8: =IF(C8="","[ Pending ]", IF(C8=The_Archive!B3, "✅ Correct", "❌ Try Again"))
B10: 3. Convert 'Amount' in Raw_Data!C2 to a Number | D10: =IF(C10="","[ Pending ]", IF(C10=The_Archive!B4, "✅ Correct", "❌ Try Again"))
B12: 4. Join Name and Code: 'Name - Code' | D12: =IF(C12="","[ Pending ]", IF(C12=The_Archive!B5, "✅ Correct", "❌ Try Again"))
B14: 5. Additional Task 5: Clean Row 6 of Raw_Data | D14: =IF(C14="","[ Pending ]", IF(C14=The_Archive!B6, "✅ Correct", "❌ Try Again"))
B16: 6. Additional Task 6: Clean Row 7 of Raw_Data | D16: =IF(C16="","[ Pending ]", IF(C16=The_Archive!B7, "✅ Correct", "❌ Try Again"))
B18: 7. Additional Task 7: Clean Row 8 of Raw_Data | D18: =IF(C18="","[ Pending ]", IF(C18=The_Archive!B8, "✅ Correct", "❌ Try Again"))
B20: 8. Additional Task 8: Clean Row 9 of Raw_Data | D20: =IF(C20="","[ Pending ]", IF(C20=The_Archive!B9, "✅ Correct", "❌ Try Again"))
B22: 9. Additional Task 9: Clean Row 10 of Raw_Data | D22: =IF(C22="","[ Pending ]", IF(C22=The_Archive!B10, "✅ Correct", "❌ Try Again"))
B24: 10. Additional Task 10: Clean Row 11 of Raw_Data | D24: =IF(C24="","[ Pending ]", IF(C24=The_Archive!B11, "✅ Correct", "❌ Try Again"))
B26: 11. Additional Task 11: Clean Row 12 of Raw_Data | D26: =IF(C26="","[ Pending ]", IF(C26=The_Archive!B12, "✅ Correct", "❌ Try Again"))
B28: 12. Additional Task 12: Clean Row 13 of Raw_Data | D28: =IF(C28="","[ Pending ]", IF(C28=The_Archive!B13, "✅ Correct", "❌ Try Again"))
B30: 13. Additional Task 13: Clean Row 14 of Raw_Data | D30: =IF(C30="","[ Pending ]", IF(C30=The_Archive!B14, "✅ Correct", "❌ Try Again"))
B32: 14. Additional Task 14: Clean Row 15 of Raw_Data | D32: =IF(C32="","[ Pending ]", IF(C32=The_Archive!B15, "✅ Correct", "❌ Try Again"))
B34: 15. Additional Task 15: Clean Row 16 of Raw_Data | D34: =IF(C34="","[ Pending ]", IF(C34=The_Archive!B16, "✅ Correct", "❌ Try Again"))
B36: 16. Additional Task 16: Clean Row 17 of Raw_Data | D36: =IF(C36="","[ Pending ]", IF(C36=The_Archive!B17, "✅ Correct", "❌ Try Again"))
B38: 17. Additional Task 17: Clean Row 18 of Raw_Data | D38: =IF(C38="","[ Pending ]", IF(C38=The_Archive!B18, "✅ Correct", "❌ Try Again"))
B40: 18. Additional Task 18: Clean Row 19 of Raw_Data | D40: =IF(C40="","[ Pending ]", IF(C40=The_Archive!B19, "✅ Correct", "❌ Try Again"))
B42: 19. Additional Task 19: Clean Row 20 of Raw_Data | D42: =IF(C42="","[ Pending ]", IF(C42=The_Archive!B20, "✅ Correct", "❌ Try Again"))
B44: 20. Additional Task 20: Clean Row 21 of Raw_Data | D44: =IF(C44="","[ Pending ]", IF(C44=The_Archive!B21, "✅ Correct", "❌ Try Again"))
B46: 21. Additional Task 21: Clean Row 22 of Raw_Data | D46: =IF(C46="","[ Pending ]", IF(C46=The_Archive!B22, "✅ Correct", "❌ Try Again"))
B48: 22. Additional Task 22: Clean Row 23 of Raw_Data | D48: =IF(C48="","[ Pending ]", IF(C48=The_Archive!B23, "✅ Correct", "❌ Try Again"))
B50: 23. Additional Task 23: Clean Row 24 of Raw_Data | D50: =IF(C50="","[ Pending ]", IF(C50=The_Archive!B24, "✅ Correct", "❌ Try Again"))
B52: 24. Additional Task 24: Clean Row 25 of Raw_Data | D52: =IF(C52="","[ Pending ]", IF(C52=The_Archive!B25, "✅ Correct", "❌ Try Again"))
B54: 25. Additional Task 25: Clean Row 26 of Raw_Data | D54: =IF(C54="","[ Pending ]", IF(C54=The_Archive!B26, "✅ Correct", "❌ Try Again"))
B56: 26. Additional Task 26: Clean Row 27 of Raw_Data | D56: =IF(C56="","[ Pending ]", IF(C56=The_Archive!B27, "✅ Correct", "❌ Try Again"))
B58: 27. Additional Task 27: Clean Row 28 of Raw_Data | D58: =IF(C58="","[ Pending ]", IF(C58=The_Archive!B28, "✅ Correct", "❌ Try Again"))
B60: 28. Additional Task 28: Clean Row 29 of Raw_Data | D60: =IF(C60="","[ Pending ]", IF(C60=The_Archive!B29, "✅ Correct", "❌ Try Again"))
B62: 29. Additional Task 29: Clean Row 30 of Raw_Data | D62: =IF(C62="","[ Pending ]", IF(C62=The_Archive!B30, "✅ Correct", "❌ Try Again"))
B64: 30. Additional Task 30: Clean Row 31 of Raw_Data | D64: =IF(C64="","[ Pending ]", IF(C64=The_Archive!B31, "✅ Correct", "❌ Try Again"))
B66: 31. Additional Task 31: Clean Row 32 of Raw_Data | D66: =IF(C66="","[ Pending ]", IF(C66=The_Archive!B32, "✅ Correct", "❌ Try Again"))
B68: 32. Additional Task 32: Clean Row 33 of Raw_Data | D68: =IF(C68="","[ Pending ]", IF(C68=The_Archive!B33, "✅ Correct", "❌ Try Again"))
B70: 33. Additional Task 33: Clean Row 34 of Raw_Data | D70: =IF(C70="","[ Pending ]", IF(C70=The_Archive!B34, "✅ Correct", "❌ Try Again"))
B72: 34. Additional Task 34: Clean Row 35 of Raw_Data | D72: =IF(C72="","[ Pending ]", IF(C72=The_Archive!B35, "✅ Correct", "❌ Try Again"))
B74: 35. Additional Task 35: Clean Row 36 of Raw_Data | D74: =IF(C74="","[ Pending ]", IF(C74=The_Archive!B36, "✅ Correct", "❌ Try Again"))
B76: 36. Additional Task 36: Clean Row 37 of Raw_Data | D76: =IF(C76="","[ Pending ]", IF(C76=The_Archive!B37, "✅ Correct", "❌ Try Again"))
B78: 37. Additional Task 37: Clean Row 38 of Raw_Data | D78: =IF(C78="","[ Pending ]", IF(C78=The_Archive!B38, "✅ Correct", "❌ Try Again"))
B80: 38. Additional Task 38: Clean Row 39 of Raw_Data | D80: =IF(C80="","[ Pending ]", IF(C80=The_Archive!B39, "✅ Correct", "❌ Try Again"))
B82: 39. Additional Task 39: Clean Row 40 of Raw_Data | D82: =IF(C82="","[ Pending ]", IF(C82=The_Archive!B40, "✅ Correct", "❌ Try Again"))
...
