Workbook

Sheet Start Here
B12: Day 12: Predictive Analytics & Forecasting
B14: Move from historical reporting to future prediction. Master Trendlines, Seasonality, and Exponential Growth.

Sheet Historical_Data
A1: Month | B1: Actual_Sales | C1: Seasonality_Index
A2: 1 | B2: 1058 | C2: 1
A3: 2 | B3: 1123 | C3: 1
A4: 3 | B4: 1156 | C4: 1
A5: 4 | B5: 1214 | C5: 1
A6: 5 | B6: 1233 | C6: 1
A7: 6 | B7: 1257 | C7: 1
A8: 7 | B8: 1371 | C8: 1
A9: 8 | B9: 1395 | C9: 1
A10: 9 | B10: 1423 | C10: 1
A11: 10 | B11: 1490 | C11: 1
A12: 11 | B12: 1538 | C12: 1
A13: 12 | B13: 1593 | C13: 1.1
... A25: 24 | B25: 2197 | C25: 1.1

Sheet The_Archive
A1: Task # | B1: Challenge | C1: Expected Formula / Term
A2: 1 | B2: Which function predicts a future value along a linear trend? | C2: FORECAST
A3: 2 | B3: What function do you use for Triple Exponential Smoothing (Seasonality)? | C3: ETS
A4: 3 | B4: How do you calculate a 3-period 'Smoothing' average? | C4: AVERAGE
A5: 4 | B5: Which function models exponential growth (compounding) instead of linear? | C5: GROWTH
A6: 5 | B6: What represents the range where the prediction is likely to fall? | C6: Confidence
A7: 6 | B7: Which chart tool automatically generates a forecast sheet with bounds? | C7: Forecast Sheet
A8: 7 | B8: In a trendline, what does 'R-Squared' measure? | C8: Squared
A9: 8 | B9: Predictive Task 8: Define logic for Seasonality detection | C9: Predict
A10: 9 | B10: Predictive Task 9: Define logic for Outlier smoothing | C10: Predict
A11: 10 | B11: Predictive Task 10: Define logic for Seasonality detection | C11: Predict
A12: 11 | B12: Predictive Task 11: Define logic for Outlier smoothing | C12: Predict
A13: 12 | B13: Predictive Task 12: Define logic for Linear Regression | C13: Predict
... A41: 40 | B41: Predictive Task 40: Define logic for Standard Error | C41: Predict

Sheet Mastery_Lab
B2: PREDICTIVE ANALYTICS DRILL
B6: 1. Which function predicts a future value along a linear trend? | D6: =IF(C6="","[ Pending ]", IF(ISNUMBER(SEARCH(The_Archive!C2, C6)), "✅ Correct", "❌ Try Again"))
B8: 2. What function do you use for Triple Exponential Smoothing (Seasonality)? | D8: =IF(C8="","[ Pending ]", IF(ISNUMBER(SEARCH(The_Archive!C3, C8)), "✅ Correct", "❌ Try Again"))
B10: 3. How do you calculate a 3-period 'Smoothing' average? | D10: =IF(C10="","[ Pending ]", IF(ISNUMBER(SEARCH(The_Archive!C4, C10)), "✅ Correct", "❌ Try Again"))
B12: 4. Which function models exponential growth (compounding) instead of linear? | D12: =IF(C12="","[ Pending ]", IF(ISNUMBER(SEARCH(The_Archive!C5, C12)), "✅ Correct", "❌ Try Again"))
B14: 5. What represents the range where the prediction is likely to fall? | D14: =IF(C14="","[ Pending ]", IF(ISNUMBER(SEARCH(The_Archive!C6, C14)), "✅ Correct", "❌ Try Again"))
B16: 6. Which chart tool automatically generates a forecast sheet with bounds? | D16: =IF(C16="","[ Pending ]", IF(ISNUMBER(SEARCH(The_Archive!C7, C16)), "✅ Correct", "❌ Try Again"))
B18: 7. In a trendline, what does 'R-Squared' measure? | D18: =IF(C18="","[ Pending ]", IF(ISNUMBER(SEARCH(The_Archive!C8, C18)), "✅ Correct", "❌ Try Again"))
B20: 8. Predictive Task 8: Define logic for Seasonality detection | D20: =IF(C20="","[ Pending ]", IF(ISNUMBER(SEARCH(The_Archive!C9, C20)), "✅ Correct", "❌ Try Again"))
B22: 9. Predictive Task 9: Define logic for Outlier smoothing | D22: =IF(C22="","[ Pending ]", IF(ISNUMBER(SEARCH(The_Archive!C10, C22)), "✅ Correct", "❌ Try Again"))
B24: 10. Predictive Task 10: Define logic for Seasonality detection | D24: =IF(C24="","[ Pending ]", IF(ISNUMBER(SEARCH(The_Archive!C11, C24)), "✅ Correct", "❌ Try Again"))
B26: 11. Predictive Task 11: Define logic for Outlier smoothing | D26: =IF(C26="","[ Pending ]", IF(ISNUMBER(SEARCH(The_Archive!C12, C26)), "✅ Correct", "❌ Try Again"))
B28: 12. Predictive Task 12: Define logic for Linear Regression | D28: =IF(C28="","[ Pending ]", IF(ISNUMBER(SEARCH(The_Archive!C13, C28)), "✅ Correct", "❌ Try Again"))
B30: 13. Predictive Task 13: Define logic for Seasonality detection | D30: =IF(C30="","[ Pending ]", IF(ISNUMBER(SEARCH(The_Archive!C14, C30)), "✅ Correct", "❌ Try Again"))
B32: 14. Predictive Task 14: Define logic for Linear Regression | D32: =IF(C32="","[ Pending ]", IF(ISNUMBER(SEARCH(The_Archive!C15, C32)), "✅ Correct", "❌ Try Again"))
B34: 15. Predictive Task 15: Define logic for Seasonality detection | D34: =IF(C34="","[ Pending ]", IF(ISNUMBER(SEARCH(The_Archive!C16, C34)), "✅ Correct", "❌ Try Again"))
B36: 16. Predictive Task 16: Define logic for Linear Regression | D36: =IF(C36="","[ Pending ]", IF(ISNUMBER(SEARCH(The_Archive!C17, C36)), "✅ Correct", "❌ Try Again"))
B38: 17. Predictive Task 17: Define logic for Linear Regression | D38: =IF(C38="","[ Pending ]", IF(ISNUMBER(SEARCH(The_Archive!C18, C38)), "✅ Correct", "❌ Try Again"))
B40: 18. Predictive Task 18: Define logic for Standard Error | D40: =IF(C40="","[ Pending ]", IF(ISNUMBER(SEARCH(The_Archive!C19, C40)), "✅ Correct", "❌ Try Again"))
B42: 19. Predictive Task 19: Define logic for Outlier smoothing | D42: =IF(C42="","[ Pending ]", IF(ISNUMBER(SEARCH(The_Archive!C20, C42)), "✅ Correct", "❌ Try Again"))
B44: 20. Predictive Task 20: Define logic for Seasonality detection | D44: =IF(C44="","[ Pending ]", IF(ISNUMBER(SEARCH(The_Archive!C21, C44)), "✅ Correct", "❌ Try Again"))
B46: 21. Predictive Task 21: Define logic for Standard Error | D46: =IF(C46="","[ Pending ]", IF(ISNUMBER(SEARCH(The_Archive!C22, C46)), "✅ Correct", "❌ Try Again"))
B48: 22. Predictive Task 22: Define logic for Standard Error | D48: =IF(C48="","[ Pending ]", IF(ISNUMBER(SEARCH(The_Archive!C23, C48)), "✅ Correct", "❌ Try Again"))
B50: 23. Predictive Task 23: Define logic for Outlier smoothing | D50: =IF(C50="","[ Pending ]", IF(ISNUMBER(SEARCH(The_Archive!C24, C50)), "✅ Correct", "❌ Try Again"))
B52: 24. Predictive Task 24: Define logic for Linear Regression | D52: =IF(C52="","[ Pending ]", IF(ISNUMBER(SEARCH(The_Archive!C25, C52)), "✅ Correct", "❌ Try Again"))
B54: 25. Predictive Task 25: Define logic for Standard Error | D54: =IF(C54="","[ Pending ]", IF(ISNUMBER(SEARCH(The_Archive!C26, C54)), "✅ Correct", "❌ Try Again"))
B56: 26. Predictive Task 26: Define logic for Outlier smoothing | D56: =IF(C56="","[ Pending ]", IF(ISNUMBER(SEARCH(The_Archive!C27, C56)), "✅ Correct", "❌ Try Again"))
B58: 27. Predictive Task 27: Define logic for Linear Regression | D58: =IF(C58="","[ Pending ]", IF(ISNUMBER(SEARCH(The_Archive!C28, C58)), "✅ Correct", "❌ Try Again"))
B60: 28. Predictive Task 28: Define logic for Linear Regression | D60: =IF(C60="","[ Pending ]", IF(ISNUMBER(SEARCH(The_Archive!C29, C60)), "✅ Correct", "❌ Try Again"))
B62: 29. Predictive Task 29: Define logic for Outlier smoothing | D62: =IF(C62="","[ Pending ]", IF(ISNUMBER(SEARCH(The_Archive!C30, C62)), "✅ Correct", "❌ Try Again"))
B64: 30. Predictive Task 30: Define logic for Outlier smoothing | D64: =IF(C64="","[ Pending ]", IF(ISNUMBER(SEARCH(The_Archive!C31, C64)), "✅ Correct", "❌ Try Again"))
B66: 31. Predictive Task 31: Define logic for Linear Regression | D66: =IF(C66="","[ Pending ]", IF(ISNUMBER(SEARCH(The_Archive!C32, C66)), "✅ Correct", "❌ Try Again"))
B68: 32. Predictive Task 32: Define logic for Standard Error | D68: =IF(C68="","[ Pending ]", IF(ISNUMBER(SEARCH(The_Archive!C33, C68)), "✅ Correct", "❌ Try Again"))
B70: 33. Predictive Task 33: Define logic for Standard Error | D70: =IF(C70="","[ Pending ]", IF(ISNUMBER(SEARCH(The_Archive!C34, C70)), "✅ Correct", "❌ Try Again"))
B72: 34. Predictive Task 34: Define logic for Standard Error | D72: =IF(C72="","[ Pending ]", IF(ISNUMBER(SEARCH(The_Archive!C35, C72)), "✅ Correct", "❌ Try Again"))
B74: 35. Predictive Task 35: Define logic for Seasonality detection | D74: =IF(C74="","[ Pending ]", IF(ISNUMBER(SEARCH(The_Archive!C36, C74)), "✅ Correct", "❌ Try Again"))
B76: 36. Predictive Task 36: Define logic for Standard Error | D76: =IF(C76="","[ Pending ]", IF(ISNUMBER(SEARCH(The_Archive!C37, C76)), "✅ Correct", "❌ Try Again"))
B78: 37. Predictive Task 37: Define logic for Seasonality detection | D78: =IF(C78="","[ Pending ]", IF(ISNUMBER(SEARCH(The_Archive!C38, C78)), "✅ Correct", "❌ Try Again"))
B80: 38. Predictive Task 38: Define logic for Standard Error | D80: =IF(C80="","[ Pending ]", IF(ISNUMBER(SEARCH(The_Archive!C39, C80)), "✅ Correct", "❌ Try Again"))
B82: 39. Predictive Task 39: Define logic for Standard Error | D82: =IF(C82="","[ Pending ]", IF(ISNUMBER(SEARCH(The_Archive!C40, C82)), "✅ Correct", "❌ Try Again"))
...
