Workbook

Sheet Start Here
B12: Day 7: Dynamic Arrays Masterclass
B14: The 'Spilling' Revolution. Build live, auto-updating dashboards with zero VLOOKUPs.

Sheet Inventory_Source
A1: ID | B1: Category | C1: Brand | D1: Price | E1: Region
A2: PRD-2001 | B2: Office | C2: Beta | D2: 481 | E2: North
A3: PRD-2002 | B3: Office | C3: Alpha | D3: 105 | E3: East
A4: PRD-2003 | B4: Office | C4: Gamma | D4: 427 | E4: South
A5: PRD-2004 | B5: Home | C5: Beta | D5: 289 | E5: South
A6: PRD-2005 | B6: Home | C6: Gamma | D6: 360 | E6: South
A7: PRD-2006 | B7: Office | C7: Gamma | D7: 326 | E7: East
A8: PRD-2007 | B8: Home | C8: Gamma | D8: 73 | E8: North
A9: PRD-2008 | B9: Office | C9: Beta | D9: 446 | E9: East
A10: PRD-2009 | B10: Tech | C10: Gamma | D10: 96 | E10: South
A11: PRD-2010 | B11: Lifestyle | C11: Delta | D11: 24 | E11: East
A12: PRD-2011 | B12: Office | C12: Beta | D12: 265 | E12: East
A13: PRD-2012 | B13: Tech | C13: Delta | D13: 122 | E13: West
... A101: PRD-2100 | B101: Office | C101: Alpha | D101: 469 | E101: West

Sheet The_Archive
A1: Task # | B1: Challenge | C1: Correct Formula / Solution
A2: 1 | B2: List all UNIQUE Categories from Inventory_Source!B:B | C2: =UNIQUE(Inventory_Source!B2:B101)
A3: 2 | B3: List all UNIQUE Brands in alphabetical order | C3: =SORT(UNIQUE(Inventory_Source!C2:C101))
A4: 3 | B4: FILTER all rows where Category is 'Tech' | C4: =FILTER(Inventory_Source!A2:E101,Inventory_Source!B2:B101="Tech")
A5: 4 | B5: FILTER all rows where Price > 400 | C5: =FILTER(Inventory_Source!A2:E101,Inventory_Source!D2:D101>400)
A6: 5 | B6: SORT the entire Inventory by Price (Ascending) | C6: =SORT(Inventory_Source!A2:E101,4,1)
A7: 6 | B7: SORT by Region then by Brand | C7: =SORTBY(Inventory_Source!A2:E101,Inventory_Source!E2:E101,1,Inventory_Source!C2:C101,1)
A8: 7 | B8: List UNIQUE Brands for the 'North' region | C8: =UNIQUE(FILTER(Inventory_Source!C2:C101,Inventory_Source!E2:E101="North"))
A9: 8 | B9: Show Top 5 items by Price (FILTER + SORT + INDEX?) | C9: =INDEX(SORT(Inventory_Source!A2:E101,4,-1),SEQUENCE(5),SEQUENCE(1,5))
A10: 9 | B10: Advanced Task 9: Build a dynamic filter for Region South | C10: =FILTER(Inventory_Source!A2:E101,Inventory_Source!E2:E101="South")
A11: 10 | B11: Advanced Task 10: Build a dynamic filter for Region East | C11: =FILTER(Inventory_Source!A2:E101,Inventory_Source!E2:E101="East")
A12: 11 | B12: Advanced Task 11: Build a dynamic filter for Region West | C12: =FILTER(Inventory_Source!A2:E101,Inventory_Source!E2:E101="West")
A13: 12 | B13: Advanced Task 12: Build a dynamic filter for Region North | C13: =FILTER(Inventory_Source!A2:E101,Inventory_Source!E2:E101="North")
A14: 13 | B14: Advanced Task 13: Build a dynamic filter for Region South | C14: =FILTER(Inventory_Source!A2:E101,Inventory_Source!E2:E101="South")
A15: 14 | B15: Advanced Task 14: Build a dynamic filter for Region East | C15: =FILTER(Inventory_Source!A2:E101,Inventory_Source!E2:E101="East")
A16: 15 | B16: Advanced Task 15: Build a dynamic filter for Region West | C16: =FILTER(Inventory_Source!A2:E101,Inventory_Source!E2:E101="West")
A17: 16 | B17: Advanced Task 16: Build a dynamic filter for Region North | C17: =FILTER(Inventory_Source!A2:E101,Inventory_Source!E2:E101="North")
A18: 17 | B18: Advanced Task 17: Build a dynamic filter for Region South | C18: =FILTER(Inventory_Source!A2:E101,Inventory_Source!E2:E101="South")
A19: 18 | B19: Advanced Task 18: Build a dynamic filter for Region East | C19: =FILTER(Inventory_Source!A2:E101,Inventory_Source!E2:E101="East")
A20: 19 | B20: Advanced Task 19: Build a dynamic filter for Region West | C20: =FILTER(Inventory_Source!A2:E101,Inventory_Source!E2:E101="West")
A21: 20 | B21: Advanced Task 20: Build a dynamic filter for Region North | C21: =FILTER(Inventory_Source!A2:E101,Inventory_Source!E2:E101="North")
A22: 21 | B22: Advanced Task 21: Build a dynamic filter for Region South | C22: =FILTER(Inventory_Source!A2:E101,Inventory_Source!E2:E101="South")
A23: 22 | B23: Advanced Task 22: Build a dynamic filter for Region East | C23: =FILTER(Inventory_Source!A2:E101,Inventory_Source!E2:E101="East")
A24: 23 | B24: Advanced Task 23: Build a dynamic filter for Region West | C24: =FILTER(Inventory_Source!A2:E101,Inventory_Source!E2:E101="West")
A25: 24 | B25: Advanced Task 24: Build a dynamic filter for Region North | C25: =FILTER(Inventory_Source!A2:E101,Inventory_Source!E2:E101="North")
A26: 25 | B26: Advanced Task 25: Build a dynamic filter for Region South | C26: =FILTER(Inventory_Source!A2:E101,Inventory_Source!E2:E101="South")
A27: 26 | B27: Advanced Task 26: Build a dynamic filter for Region East | C27: =FILTER(Inventory_Source!A2:E101,Inventory_Source!E2:E101="East")
A28: 27 | B28: Advanced Task 27: Build a dynamic filter for Region West | C28: =FILTER(Inventory_Source!A2:E101,Inventory_Source!E2:E101="West")
A29: 28 | B29: Advanced Task 28: Build a dynamic filter for Region North | C29: =FILTER(Inventory_Source!A2:E101,Inventory_Source!E2:E101="North")
A30: 29 | B30: Advanced Task 29: Build a dynamic filter for Region South | C30: =FILTER(Inventory_Source!A2:E101,Inventory_Source!E2:E101="South")
A31: 30 | B31: Advanced Task 30: Build a dynamic filter for Region East | C31: =FILTER(Inventory_Source!A2:E101,Inventory_Source!E2:E101="East")
A32: 31 | B32: Advanced Task 31: Build a dynamic filter for Region West | C32: =FILTER(Inventory_Source!A2:E101,Inventory_Source!E2:E101="West")
A33: 32 | B33: Advanced Task 32: Build a dynamic filter for Region North | C33: =FILTER(Inventory_Source!A2:E101,Inventory_Source!E2:E101="North")
A34: 33 | B34: Advanced Task 33: Build a dynamic filter for Region South | C34: =FILTER(Inventory_Source!A2:E101,Inventory_Source!E2:E101="South")
A35: 34 | B35: Advanced Task 34: Build a dynamic filter for Region East | C35: =FILTER(Inventory_Source!A2:E101,Inventory_Source!E2:E101="East")
A36: 35 | B36: Advanced Task 35: Build a dynamic filter for Region West | C36: =FILTER(Inventory_Source!A2:E101,Inventory_Source!E2:E101="West")
A37: 36 | B37: Advanced Task 36: Build a dynamic filter for Region North | C37: =FILTER(Inventory_Source!A2:E101,Inventory_Source!E2:E101="North")
A38: 37 | B38: Advanced Task 37: Build a dynamic filter for Region South | C38: =FILTER(Inventory_Source!A2:E101,Inventory_Source!E2:E101="South")
A39: 38 | B39: Advanced Task 38: Build a dynamic filter for Region East | C39: =FILTER(Inventory_Source!A2:E101,Inventory_Source!E2:E101="East")
A40: 39 | B40: Advanced Task 39: Build a dynamic filter for Region West | C40: =FILTER(Inventory_Source!A2:E101,Inventory_Source!E2:E101="West")
...

Sheet Mastery_Lab
B2: DYNAMIC ARRAYS DRILL
B6: 1. List all UNIQUE Categories from Inventory_Source!B:B | D6: =IF(C6="","[ Pending ]", IF(C6=The_Archive!C2, "✅ Correct", "❌ Try Again"))
B8: 2. List all UNIQUE Brands in alphabetical order | D8: =IF(C8="","[ Pending ]", IF(C8=The_Archive!C3, "✅ Correct", "❌ Try Again"))
B10: 3. FILTER all rows where Category is 'Tech' | D10: =IF(C10="","[ Pending ]", IF(C10=The_Archive!C4, "✅ Correct", "❌ Try Again"))
B12: 4. FILTER all rows where Price > 400 | D12: =IF(C12="","[ Pending ]", IF(C12=The_Archive!C5, "✅ Correct", "❌ Try Again"))
B14: 5. SORT the entire Inventory by Price (Ascending) | D14: =IF(C14="","[ Pending ]", IF(C14=The_Archive!C6, "✅ Correct", "❌ Try Again"))
B16: 6. SORT by Region then by Brand | D16: =IF(C16="","[ Pending ]", IF(C16=The_Archive!C7, "✅ Correct", "❌ Try Again"))
B18: 7. List UNIQUE Brands for the 'North' region | D18: =IF(C18="","[ Pending ]", IF(C18=The_Archive!C8, "✅ Correct", "❌ Try Again"))
B20: 8. Show Top 5 items by Price (FILTER + SORT + INDEX?) | D20: =IF(C20="","[ Pending ]", IF(C20=The_Archive!C9, "✅ Correct", "❌ Try Again"))
B22: 9. Advanced Task 9: Build a dynamic filter for Region South | D22: =IF(C22="","[ Pending ]", IF(C22=The_Archive!C10, "✅ Correct", "❌ Try Again"))
B24: 10. Advanced Task 10: Build a dynamic filter for Region East | D24: =IF(C24="","[ Pending ]", IF(C24=The_Archive!C11, "✅ Correct", "❌ Try Again"))
B26: 11. Advanced Task 11: Build a dynamic filter for Region West | D26: =IF(C26="","[ Pending ]", IF(C26=The_Archive!C12, "✅ Correct", "❌ Try Again"))
B28: 12. Advanced Task 12: Build a dynamic filter for Region North | D28: =IF(C28="","[ Pending ]", IF(C28=The_Archive!C13, "✅ Correct", "❌ Try Again"))
B30: 13. Advanced Task 13: Build a dynamic filter for Region South | D30: =IF(C30="","[ Pending ]", IF(C30=The_Archive!C14, "✅ Correct", "❌ Try Again"))
B32: 14. Advanced Task 14: Build a dynamic filter for Region East | D32: =IF(C32="","[ Pending ]", IF(C32=The_Archive!C15, "✅ Correct", "❌ Try Again"))
B34: 15. Advanced Task 15: Build a dynamic filter for Region West | D34: =IF(C34="","[ Pending ]", IF(C34=The_Archive!C16, "✅ Correct", "❌ Try Again"))
B36: 16. Advanced Task 16: Build a dynamic filter for Region North | D36: =IF(C36="","[ Pending ]", IF(C36=The_Archive!C17, "✅ Correct", "❌ Try Again"))
B38: 17. Advanced Task 17: Build a dynamic filter for Region South | D38: =IF(C38="","[ Pending ]", IF(C38=The_Archive!C18, "✅ Correct", "❌ Try Again"))
B40: 18. Advanced Task 18: Build a dynamic filter for Region East | D40: =IF(C40="","[ Pending ]", IF(C40=The_Archive!C19, "✅ Correct", "❌ Try Again"))
B42: 19. Advanced Task 19: Build a dynamic filter for Region West | D42: =IF(C42="","[ Pending ]", IF(C42=The_Archive!C20, "✅ Correct", "❌ Try Again"))
B44: 20. Advanced Task 20: Build a dynamic filter for Region North | D44: =IF(C44="","[ Pending ]", IF(C44=The_Archive!C21, "✅ Correct", "❌ Try Again"))
B46: 21. Advanced Task 21: Build a dynamic filter for Region South | D46: =IF(C46="","[ Pending ]", IF(C46=The_Archive!C22, "✅ Correct", "❌ Try Again"))
B48: 22. Advanced Task 22: Build a dynamic filter for Region East | D48: =IF(C48="","[ Pending ]", IF(C48=The_Archive!C23, "✅ Correct", "❌ Try Again"))
B50: 23. Advanced Task 23: Build a dynamic filter for Region West | D50: =IF(C50="","[ Pending ]", IF(C50=The_Archive!C24, "✅ Correct", "❌ Try Again"))
B52: 24. Advanced Task 24: Build a dynamic filter for Region North | D52: =IF(C52="","[ Pending ]", IF(C52=The_Archive!C25, "✅ Correct", "❌ Try Again"))
B54: 25. Advanced Task 25: Build a dynamic filter for Region South | D54: =IF(C54="","[ Pending ]", IF(C54=The_Archive!C26, "✅ Correct", "❌ Try Again"))
B56: 26. Advanced Task 26: Build a dynamic filter for Region East | D56: =IF(C56="","[ Pending ]", IF(C56=The_Archive!C27, "✅ Correct", "❌ Try Again"))
B58: 27. Advanced Task 27: Build a dynamic filter for Region West | D58: =IF(C58="","[ Pending ]", IF(C58=The_Archive!C28, "✅ Correct", "❌ Try Again"))
B60: 28. Advanced Task 28: Build a dynamic filter for Region North | D60: =IF(C60="","[ Pending ]", IF(C60=The_Archive!C29, "✅ Correct", "❌ Try Again"))
B62: 29. Advanced Task 29: Build a dynamic filter for Region South | D62: =IF(C62="","[ Pending ]", IF(C62=The_Archive!C30, "✅ Correct", "❌ Try Again"))
B64: 30. Advanced Task 30: Build a dynamic filter for Region East | D64: =IF(C64="","[ Pending ]", IF(C64=The_Archive!C31, "✅ Correct", "❌ Try Again"))
B66: 31. Advanced Task 31: Build a dynamic filter for Region West | D66: =IF(C66="","[ Pending ]", IF(C66=The_Archive!C32, "✅ Correct", "❌ Try Again"))
B68: 32. Advanced Task 32: Build a dynamic filter for Region North | D68: =IF(C68="","[ Pending ]", IF(C68=The_Archive!C33, "✅ Correct", "❌ Try Again"))
B70: 33. Advanced Task 33: Build a dynamic filter for Region South | D70: =IF(C70="","[ Pending ]", IF(C70=The_Archive!C34, "✅ Correct", "❌ Try Again"))
B72: 34. Advanced Task 34: Build a dynamic filter for Region East | D72: =IF(C72="","[ Pending ]", IF(C72=The_Archive!C35, "✅ Correct", "❌ Try Again"))
B74: 35. Advanced Task 35: Build a dynamic filter for Region West | D74: =IF(C74="","[ Pending ]", IF(C74=The_Archive!C36, "✅ Correct", "❌ Try Again"))
B76: 36. Advanced Task 36: Build a dynamic filter for Region North | D76: =IF(C76="","[ Pending ]", IF(C76=The_Archive!C37, "✅ Correct", "❌ Try Again"))
B78: 37. Advanced Task 37: Build a dynamic filter for Region South | D78: =IF(C78="","[ Pending ]", IF(C78=The_Archive!C38, "✅ Correct", "❌ Try Again"))
B80: 38. Advanced Task 38: Build a dynamic filter for Region East | D80: =IF(C80="","[ Pending ]", IF(C80=The_Archive!C39, "✅ Correct", "❌ Try Again"))
B82: 39. Advanced Task 39: Build a dynamic filter for Region West | D82: =IF(C82="","[ Pending ]", IF(C82=The_Archive!C40, "✅ Correct", "❌ Try Again"))
...
