Workbook

Sheet Start Here
B12: Day 9: Power Pivot & Data Modeling
B14: Break the 1-million row limit. Master relational data modeling and DAX for enterprise-scale intelligence.

Sheet Fact_Sales
A1: Sale ID | B1: Date | C1: ProductID | D1: Quantity | E1: RegionID
A2: S-1001 | B2: 2023-01-01 | C2: P-2 | D2: 3 | E2: R-4
A3: S-1002 | B3: 2023-01-01 | C3: P-8 | D3: 5 | E3: R-2
A4: S-1003 | B4: 2023-01-01 | C4: P-4 | D4: 3 | E4: R-2
A5: S-1004 | B5: 2023-01-01 | C5: P-1 | D5: 5 | E5: R-4
A6: S-1005 | B6: 2023-01-01 | C6: P-10 | D6: 5 | E6: R-1
A7: S-1006 | B7: 2023-01-01 | C7: P-7 | D7: 4 | E7: R-1
A8: S-1007 | B8: 2023-01-01 | C8: P-7 | D8: 1 | E8: R-2
A9: S-1008 | B9: 2023-01-01 | C9: P-6 | D9: 3 | E9: R-1
A10: S-1009 | B10: 2023-01-01 | C10: P-9 | D10: 4 | E10: R-1
A11: S-1010 | B11: 2023-01-01 | C11: P-7 | D11: 3 | E11: R-3
A12: S-1011 | B12: 2023-01-01 | C12: P-2 | D12: 2 | E12: R-1
A13: S-1012 | B13: 2023-01-01 | C13: P-10 | D13: 3 | E13: R-1
... A101: S-1100 | B101: 2023-01-01 | C101: P-5 | D101: 4 | E101: R-4

Sheet Dim_Products
A1: ProductID | B1: Product Name | C1: Category | D1: Price
A2: P-1 | B2: Alpha | C2: Tech | D2: 892
A3: P-2 | B3: Beta | C3: Tech | D3: 503
A4: P-3 | B4: Gamma | C4: Tech | D4: 213
A5: P-4 | B5: Delta | C5: Tech | D5: 901
A6: P-5 | B6: Epsilon | C6: Tech | D6: 576
A7: P-6 | B7: Zeta | C7: Home | D7: 143
A8: P-7 | B8: Eta | C8: Home | D8: 259
A9: P-8 | B9: Theta | C9: Home | D9: 485
A10: P-9 | B10: Iota | C10: Home | D10: 966
A11: P-10 | B11: Kappa | C11: Home | D11: 777

Sheet Dim_Regions
A1: RegionID | B1: Region Name | C1: Market
A2: R-1 | B2: North America | C2: Developed
A3: R-2 | B3: Europe | C3: Developed
A4: R-3 | B4: Asia | C4: Emerging
A5: R-4 | B5: Africa | C5: Emerging

Sheet The_Archive
A1: Task # | B1: Challenge | C1: Expected Concept / DAX
A2: 1 | B2: What is the relationship between Fact_Sales and Dim_Products? (1:Many, 1:1, Many:Many) | C2: 1:Many
A3: 2 | B3: Which column is the Foreign Key in Fact_Sales? | C3: ProductID
A4: 3 | B4: DAX: Write a measure to calculate 'Total Quantity' | C4: SUM
A5: 4 | B5: DAX: Write a measure for 'Total Sales' (Price * Quantity) | C5: SUMX
A6: 5 | B6: What is the difference between a Calculated Column and a Measure? | C6: Runtime
A7: 6 | B7: Which tab do you use to manage table relationships in Power Pivot? | C7: Diagram View
A8: 7 | B8: How do you hide a column from the Client Tools (Pivot Tables)? | C8: Hide
A9: 8 | B9: Advanced Modeling Task 8: Define logic for Time Intelligence | C9: DAX
A10: 9 | B10: Advanced Modeling Task 9: Define logic for Calculated Fields | C10: DAX
A11: 10 | B11: Advanced Modeling Task 10: Define logic for Calculated Fields | C11: DAX
A12: 11 | B12: Advanced Modeling Task 11: Define logic for Calculated Fields | C12: DAX
A13: 12 | B13: Advanced Modeling Task 12: Define logic for Calculated Fields | C13: DAX
... A41: 40 | B41: Advanced Modeling Task 40: Define logic for Measures | C41: DAX

Sheet Mastery_Lab
B2: DATA MODELING & DAX DRILL
B6: 1. What is the relationship between Fact_Sales and Dim_Products? (1:Many, 1:1, Many:Many) | D6: =IF(C6="","[ Pending ]", IF(ISNUMBER(SEARCH(The_Archive!C2, C6)), "✅ Correct", "❌ Try Again"))
B8: 2. Which column is the Foreign Key in Fact_Sales? | D8: =IF(C8="","[ Pending ]", IF(ISNUMBER(SEARCH(The_Archive!C3, C8)), "✅ Correct", "❌ Try Again"))
B10: 3. DAX: Write a measure to calculate 'Total Quantity' | D10: =IF(C10="","[ Pending ]", IF(ISNUMBER(SEARCH(The_Archive!C4, C10)), "✅ Correct", "❌ Try Again"))
B12: 4. DAX: Write a measure for 'Total Sales' (Price * Quantity) | D12: =IF(C12="","[ Pending ]", IF(ISNUMBER(SEARCH(The_Archive!C5, C12)), "✅ Correct", "❌ Try Again"))
B14: 5. What is the difference between a Calculated Column and a Measure? | D14: =IF(C14="","[ Pending ]", IF(ISNUMBER(SEARCH(The_Archive!C6, C14)), "✅ Correct", "❌ Try Again"))
B16: 6. Which tab do you use to manage table relationships in Power Pivot? | D16: =IF(C16="","[ Pending ]", IF(ISNUMBER(SEARCH(The_Archive!C7, C16)), "✅ Correct", "❌ Try Again"))
B18: 7. How do you hide a column from the Client Tools (Pivot Tables)? | D18: =IF(C18="","[ Pending ]", IF(ISNUMBER(SEARCH(The_Archive!C8, C18)), "✅ Correct", "❌ Try Again"))
B20: 8. Advanced Modeling Task 8: Define logic for Time Intelligence | D20: =IF(C20="","[ Pending ]", IF(ISNUMBER(SEARCH(The_Archive!C9, C20)), "✅ Correct", "❌ Try Again"))
B22: 9. Advanced Modeling Task 9: Define logic for Calculated Fields | D22: =IF(C22="","[ Pending ]", IF(ISNUMBER(SEARCH(The_Archive!C10, C22)), "✅ Correct", "❌ Try Again"))
B24: 10. Advanced Modeling Task 10: Define logic for Calculated Fields | D24: =IF(C24="","[ Pending ]", IF(ISNUMBER(SEARCH(The_Archive!C11, C24)), "✅ Correct", "❌ Try Again"))
B26: 11. Advanced Modeling Task 11: Define logic for Calculated Fields | D26: =IF(C26="","[ Pending ]", IF(ISNUMBER(SEARCH(The_Archive!C12, C26)), "✅ Correct", "❌ Try Again"))
B28: 12. Advanced Modeling Task 12: Define logic for Calculated Fields | D28: =IF(C28="","[ Pending ]", IF(ISNUMBER(SEARCH(The_Archive!C13, C28)), "✅ Correct", "❌ Try Again"))
B30: 13. Advanced Modeling Task 13: Define logic for Star Schema | D30: =IF(C30="","[ Pending ]", IF(ISNUMBER(SEARCH(The_Archive!C14, C30)), "✅ Correct", "❌ Try Again"))
B32: 14. Advanced Modeling Task 14: Define logic for Star Schema | D32: =IF(C32="","[ Pending ]", IF(ISNUMBER(SEARCH(The_Archive!C15, C32)), "✅ Correct", "❌ Try Again"))
B34: 15. Advanced Modeling Task 15: Define logic for Time Intelligence | D34: =IF(C34="","[ Pending ]", IF(ISNUMBER(SEARCH(The_Archive!C16, C34)), "✅ Correct", "❌ Try Again"))
B36: 16. Advanced Modeling Task 16: Define logic for Measures | D36: =IF(C36="","[ Pending ]", IF(ISNUMBER(SEARCH(The_Archive!C17, C36)), "✅ Correct", "❌ Try Again"))
B38: 17. Advanced Modeling Task 17: Define logic for Time Intelligence | D38: =IF(C38="","[ Pending ]", IF(ISNUMBER(SEARCH(The_Archive!C18, C38)), "✅ Correct", "❌ Try Again"))
B40: 18. Advanced Modeling Task 18: Define logic for Star Schema | D40: =IF(C40="","[ Pending ]", IF(ISNUMBER(SEARCH(The_Archive!C19, C40)), "✅ Correct", "❌ Try Again"))
B42: 19. Advanced Modeling Task 19: Define logic for Star Schema | D42: =IF(C42="","[ Pending ]", IF(ISNUMBER(SEARCH(The_Archive!C20, C42)), "✅ Correct", "❌ Try Again"))
B44: 20. Advanced Modeling Task 20: Define logic for Time Intelligence | D44: =IF(C44="","[ Pending ]", IF(ISNUMBER(SEARCH(The_Archive!C21, C44)), "✅ Correct", "❌ Try Again"))
B46: 21. Advanced Modeling Task 21: Define logic for Star Schema | D46: =IF(C46="","[ Pending ]", IF(ISNUMBER(SEARCH(The_Archive!C22, C46)), "✅ Correct", "❌ Try Again"))
B48: 22. Advanced Modeling Task 22: Define logic for Star Schema | D48: =IF(C48="","[ Pending ]", IF(ISNUMBER(SEARCH(The_Archive!C23, C48)), "✅ Correct", "❌ Try Again"))
B50: 23. Advanced Modeling Task 23: Define logic for Time Intelligence | D50: =IF(C50="","[ Pending ]", IF(ISNUMBER(SEARCH(The_Archive!C24, C50)), "✅ Correct", "❌ Try Again"))
B52: 24. Advanced Modeling Task 24: Define logic for Measures | D52: =IF(C52="","[ Pending ]", IF(ISNUMBER(SEARCH(The_Archive!C25, C52)), "✅ Correct", "❌ Try Again"))
B54: 25. Advanced Modeling Task 25: Define logic for Calculated Fields | D54: =IF(C54="","[ Pending ]", IF(ISNUMBER(SEARCH(The_Archive!C26, C54)), "✅ Correct", "❌ Try Again"))
B56: 26. Advanced Modeling Task 26: Define logic for Measures | D56: =IF(C56="","[ Pending ]", IF(ISNUMBER(SEARCH(The_Archive!C27, C56)), "✅ Correct", "❌ Try Again"))
B58: 27. Advanced Modeling Task 27: Define logic for Star Schema | D58: =IF(C58="","[ Pending ]", IF(ISNUMBER(SEARCH(The_Archive!C28, C58)), "✅ Correct", "❌ Try Again"))
B60: 28. Advanced Modeling Task 28: Define logic for Time Intelligence | D60: =IF(C60="","[ Pending ]", IF(ISNUMBER(SEARCH(The_Archive!C29, C60)), "✅ Correct", "❌ Try Again"))
B62: 29. Advanced Modeling Task 29: Define logic for Time Intelligence | D62: =IF(C62="","[ Pending ]", IF(ISNUMBER(SEARCH(The_Archive!C30, C62)), "✅ Correct", "❌ Try Again"))
B64: 30. Advanced Modeling Task 30: Define logic for Time Intelligence | D64: =IF(C64="","[ Pending ]", IF(ISNUMBER(SEARCH(The_Archive!C31, C64)), "✅ Correct", "❌ Try Again"))
B66: 31. Advanced Modeling Task 31: Define logic for Time Intelligence | D66: =IF(C66="","[ Pending ]", IF(ISNUMBER(SEARCH(The_Archive!C32, C66)), "✅ Correct", "❌ Try Again"))
B68: 32. Advanced Modeling Task 32: Define logic for Measures | D68: =IF(C68="","[ Pending ]", IF(ISNUMBER(SEARCH(The_Archive!C33, C68)), "✅ Correct", "❌ Try Again"))
B70: 33. Advanced Modeling Task 33: Define logic for Star Schema | D70: =IF(C70="","[ Pending ]", IF(ISNUMBER(SEARCH(The_Archive!C34, C70)), "✅ Correct", "❌ Try Again"))
B72: 34. Advanced Modeling Task 34: Define logic for Time Intelligence | D72: =IF(C72="","[ Pending ]", IF(ISNUMBER(SEARCH(The_Archive!C35, C72)), "✅ Correct", "❌ Try Again"))
B74: 35. Advanced Modeling Task 35: Define logic for Measures | D74: =IF(C74="","[ Pending ]", IF(ISNUMBER(SEARCH(The_Archive!C36, C74)), "✅ Correct", "❌ Try Again"))
B76: 36. Advanced Modeling Task 36: Define logic for Calculated Fields | D76: =IF(C76="","[ Pending ]", IF(ISNUMBER(SEARCH(The_Archive!C37, C76)), "✅ Correct", "❌ Try Again"))
B78: 37. Advanced Modeling Task 37: Define logic for Calculated Fields | D78: =IF(C78="","[ Pending ]", IF(ISNUMBER(SEARCH(The_Archive!C38, C78)), "✅ Correct", "❌ Try Again"))
B80: 38. Advanced Modeling Task 38: Define logic for Measures | D80: =IF(C80="","[ Pending ]", IF(ISNUMBER(SEARCH(The_Archive!C39, C80)), "✅ Correct", "❌ Try Again"))
B82: 39. Advanced Modeling Task 39: Define logic for Time Intelligence | D82: =IF(C82="","[ Pending ]", IF(ISNUMBER(SEARCH(The_Archive!C40, C82)), "✅ Correct", "❌ Try Again"))
...
