Workbook

Sheet Start Here
B10: Day 3: INDEX & MATCH Architecture
B12: Bulletproof lookups. The most modular way to retrieve data in Excel. Learn 2-way matrix lookups.

Sheet Matrix_Data
A1: ID | B1: Q1 Sales | C1: Q2 Sales | D1: Q3 Sales | E1: Q4 Sales
A2: EMP-101 | B2: 4066 | C2: 3501 | D2: 3355 | E2: 1035
A3: EMP-102 | B3: 2953 | C3: 2916 | D3: 4565 | E3: 1792
A4: EMP-103 | B4: 2739 | C4: 2845 | D4: 3013 | E4: 4431
A5: EMP-104 | B5: 4093 | C5: 1801 | D5: 1704 | E5: 3212
A6: EMP-105 | B6: 4925 | C6: 3613 | D6: 4751 | E6: 1575
A7: EMP-106 | B7: 4903 | C7: 3578 | D7: 1389 | E7: 3677
A8: EMP-107 | B8: 2693 | C8: 2309 | D8: 1855 | E8: 3869
A9: EMP-108 | B9: 2337 | C9: 3959 | D9: 1691 | E9: 4382
A10: EMP-109 | B10: 1513 | C10: 2767 | D10: 2469 | E10: 3976
A11: EMP-110 | B11: 2502 | C11: 4342 | D11: 3493 | E11: 1136
A12: EMP-111 | B12: 1141 | C12: 2444 | D12: 2162 | E12: 1418
A13: EMP-112 | B13: 4912 | C13: 1613 | D13: 1240 | E13: 4884
... A101: EMP-200 | B101: 4201 | C101: 4574 | D101: 4890 | E101: 1946

Sheet The_Archive
A1: Task # | B1: Expected Result
A2: 1 | B2: =INDEX(Matrix_Data!B:B,MATCH("EMP-101",Matrix_Data!A:A,0))
A3: 2 | B3: =INDEX(Matrix_Data!E:E,MATCH("EMP-110",Matrix_Data!A:A,0))
A4: 3 | B4: =INDEX(Matrix_Data!A:E,MATCH("EMP-120",Matrix_Data!A:A,0),MATCH("Q3 Sales",Matrix_Data!A1:E1,0))
A5: 4 | B5: =INDEX(Matrix_Data!B:B,MATCH("EMP-104",Matrix_Data!A:A,0))
A6: 5 | B6: =INDEX(Matrix_Data!B:B,MATCH("EMP-105",Matrix_Data!A:A,0))
A7: 6 | B7: =INDEX(Matrix_Data!B:B,MATCH("EMP-106",Matrix_Data!A:A,0))
A8: 7 | B8: =INDEX(Matrix_Data!B:B,MATCH("EMP-107",Matrix_Data!A:A,0))
A9: 8 | B9: =INDEX(Matrix_Data!B:B,MATCH("EMP-108",Matrix_Data!A:A,0))
A10: 9 | B10: =INDEX(Matrix_Data!B:B,MATCH("EMP-109",Matrix_Data!A:A,0))
A11: 10 | B11: =INDEX(Matrix_Data!B:B,MATCH("EMP-110",Matrix_Data!A:A,0))
A12: 11 | B12: =INDEX(Matrix_Data!B:B,MATCH("EMP-111",Matrix_Data!A:A,0))
A13: 12 | B13: =INDEX(Matrix_Data!B:B,MATCH("EMP-112",Matrix_Data!A:A,0))
A14: 13 | B14: =INDEX(Matrix_Data!B:B,MATCH("EMP-113",Matrix_Data!A:A,0))
A15: 14 | B15: =INDEX(Matrix_Data!B:B,MATCH("EMP-114",Matrix_Data!A:A,0))
A16: 15 | B16: =INDEX(Matrix_Data!B:B,MATCH("EMP-115",Matrix_Data!A:A,0))
A17: 16 | B17: =INDEX(Matrix_Data!B:B,MATCH("EMP-116",Matrix_Data!A:A,0))
A18: 17 | B18: =INDEX(Matrix_Data!B:B,MATCH("EMP-117",Matrix_Data!A:A,0))
A19: 18 | B19: =INDEX(Matrix_Data!B:B,MATCH("EMP-118",Matrix_Data!A:A,0))
A20: 19 | B20: =INDEX(Matrix_Data!B:B,MATCH("EMP-119",Matrix_Data!A:A,0))
A21: 20 | B21: =INDEX(Matrix_Data!B:B,MATCH("EMP-120",Matrix_Data!A:A,0))
A22: 21 | B22: =INDEX(Matrix_Data!B:B,MATCH("EMP-121",Matrix_Data!A:A,0))
A23: 22 | B23: =INDEX(Matrix_Data!B:B,MATCH("EMP-122",Matrix_Data!A:A,0))
A24: 23 | B24: =INDEX(Matrix_Data!B:B,MATCH("EMP-123",Matrix_Data!A:A,0))
A25: 24 | B25: =INDEX(Matrix_Data!B:B,MATCH("EMP-124",Matrix_Data!A:A,0))
A26: 25 | B26: =INDEX(Matrix_Data!B:B,MATCH("EMP-125",Matrix_Data!A:A,0))
A27: 26 | B27: =INDEX(Matrix_Data!B:B,MATCH("EMP-126",Matrix_Data!A:A,0))
A28: 27 | B28: =INDEX(Matrix_Data!B:B,MATCH("EMP-127",Matrix_Data!A:A,0))
A29: 28 | B29: =INDEX(Matrix_Data!B:B,MATCH("EMP-128",Matrix_Data!A:A,0))
A30: 29 | B30: =INDEX(Matrix_Data!B:B,MATCH("EMP-129",Matrix_Data!A:A,0))
A31: 30 | B31: =INDEX(Matrix_Data!B:B,MATCH("EMP-130",Matrix_Data!A:A,0))
A32: 31 | B32: =INDEX(Matrix_Data!B:B,MATCH("EMP-131",Matrix_Data!A:A,0))
A33: 32 | B33: =INDEX(Matrix_Data!B:B,MATCH("EMP-132",Matrix_Data!A:A,0))
A34: 33 | B34: =INDEX(Matrix_Data!B:B,MATCH("EMP-133",Matrix_Data!A:A,0))
A35: 34 | B35: =INDEX(Matrix_Data!B:B,MATCH("EMP-134",Matrix_Data!A:A,0))
A36: 35 | B36: =INDEX(Matrix_Data!B:B,MATCH("EMP-135",Matrix_Data!A:A,0))
A37: 36 | B37: =INDEX(Matrix_Data!B:B,MATCH("EMP-136",Matrix_Data!A:A,0))
A38: 37 | B38: =INDEX(Matrix_Data!B:B,MATCH("EMP-137",Matrix_Data!A:A,0))
A39: 38 | B39: =INDEX(Matrix_Data!B:B,MATCH("EMP-138",Matrix_Data!A:A,0))
A40: 39 | B40: =INDEX(Matrix_Data!B:B,MATCH("EMP-139",Matrix_Data!A:A,0))
...

Sheet Mastery_Lab
B2: INDEX & MATCH MASTERY DRILL
B6: 1. Find Q1 Sales for EMP-101 using INDEX & MATCH | D6: =IF(C6="","[ Pending ]", IF(C6=The_Archive!B2, "✅ Correct", "❌ Try Again"))
B8: 2. Find Q4 Sales for EMP-110 | D8: =IF(C8="","[ Pending ]", IF(C8=The_Archive!B3, "✅ Correct", "❌ Try Again"))
B10: 3. 2-Way Lookup: Find 'Q3 Sales' for 'EMP-120' | D10: =IF(C10="","[ Pending ]", IF(C10=The_Archive!B4, "✅ Correct", "❌ Try Again"))
B12: 4. Additional Task 4: Lookup Sales for EMP-104 | D12: =IF(C12="","[ Pending ]", IF(C12=The_Archive!B5, "✅ Correct", "❌ Try Again"))
B14: 5. Additional Task 5: Lookup Sales for EMP-105 | D14: =IF(C14="","[ Pending ]", IF(C14=The_Archive!B6, "✅ Correct", "❌ Try Again"))
B16: 6. Additional Task 6: Lookup Sales for EMP-106 | D16: =IF(C16="","[ Pending ]", IF(C16=The_Archive!B7, "✅ Correct", "❌ Try Again"))
B18: 7. Additional Task 7: Lookup Sales for EMP-107 | D18: =IF(C18="","[ Pending ]", IF(C18=The_Archive!B8, "✅ Correct", "❌ Try Again"))
B20: 8. Additional Task 8: Lookup Sales for EMP-108 | D20: =IF(C20="","[ Pending ]", IF(C20=The_Archive!B9, "✅ Correct", "❌ Try Again"))
B22: 9. Additional Task 9: Lookup Sales for EMP-109 | D22: =IF(C22="","[ Pending ]", IF(C22=The_Archive!B10, "✅ Correct", "❌ Try Again"))
B24: 10. Additional Task 10: Lookup Sales for EMP-110 | D24: =IF(C24="","[ Pending ]", IF(C24=The_Archive!B11, "✅ Correct", "❌ Try Again"))
B26: 11. Additional Task 11: Lookup Sales for EMP-111 | D26: =IF(C26="","[ Pending ]", IF(C26=The_Archive!B12, "✅ Correct", "❌ Try Again"))
B28: 12. Additional Task 12: Lookup Sales for EMP-112 | D28: =IF(C28="","[ Pending ]", IF(C28=The_Archive!B13, "✅ Correct", "❌ Try Again"))
B30: 13. Additional Task 13: Lookup Sales for EMP-113 | D30: =IF(C30="","[ Pending ]", IF(C30=The_Archive!B14, "✅ Correct", "❌ Try Again"))
B32: 14. Additional Task 14: Lookup Sales for EMP-114 | D32: =IF(C32="","[ Pending ]", IF(C32=The_Archive!B15, "✅ Correct", "❌ Try Again"))
B34: 15. Additional Task 15: Lookup Sales for EMP-115 | D34: =IF(C34="","[ Pending ]", IF(C34=The_Archive!B16, "✅ Correct", "❌ Try Again"))
B36: 16. Additional Task 16: Lookup Sales for EMP-116 | D36: =IF(C36="","[ Pending ]", IF(C36=The_Archive!B17, "✅ Correct", "❌ Try Again"))
B38: 17. Additional Task 17: Lookup Sales for EMP-117 | D38: =IF(C38="","[ Pending ]", IF(C38=The_Archive!B18, "✅ Correct", "❌ Try Again"))
B40: 18. Additional Task 18: Lookup Sales for EMP-118 | D40: =IF(C40="","[ Pending ]", IF(C40=The_Archive!B19, "✅ Correct", "❌ Try Again"))
B42: 19. Additional Task 19: Lookup Sales for EMP-119 | D42: =IF(C42="","[ Pending ]", IF(C42=The_Archive!B20, "✅ Correct", "❌ Try Again"))
B44: 20. Additional Task 20: Lookup Sales for EMP-120 | D44: =IF(C44="","[ Pending ]", IF(C44=The_Archive!B21, "✅ Correct", "❌ Try Again"))
B46: 21. Additional Task 21: Lookup Sales for EMP-121 | D46: =IF(C46="","[ Pending ]", IF(C46=The_Archive!B22, "✅ Correct", "❌ Try Again"))
B48: 22. Additional Task 22: Lookup Sales for EMP-122 | D48: =IF(C48="","[ Pending ]", IF(C48=The_Archive!B23, "✅ Correct", "❌ Try Again"))
B50: 23. Additional Task 23: Lookup Sales for EMP-123 | D50: =IF(C50="","[ Pending ]", IF(C50=The_Archive!B24, "✅ Correct", "❌ Try Again"))
B52: 24. Additional Task 24: Lookup Sales for EMP-124 | D52: =IF(C52="","[ Pending ]", IF(C52=The_Archive!B25, "✅ Correct", "❌ Try Again"))
B54: 25. Additional Task 25: Lookup Sales for EMP-125 | D54: =IF(C54="","[ Pending ]", IF(C54=The_Archive!B26, "✅ Correct", "❌ Try Again"))
B56: 26. Additional Task 26: Lookup Sales for EMP-126 | D56: =IF(C56="","[ Pending ]", IF(C56=The_Archive!B27, "✅ Correct", "❌ Try Again"))
B58: 27. Additional Task 27: Lookup Sales for EMP-127 | D58: =IF(C58="","[ Pending ]", IF(C58=The_Archive!B28, "✅ Correct", "❌ Try Again"))
B60: 28. Additional Task 28: Lookup Sales for EMP-128 | D60: =IF(C60="","[ Pending ]", IF(C60=The_Archive!B29, "✅ Correct", "❌ Try Again"))
B62: 29. Additional Task 29: Lookup Sales for EMP-129 | D62: =IF(C62="","[ Pending ]", IF(C62=The_Archive!B30, "✅ Correct", "❌ Try Again"))
B64: 30. Additional Task 30: Lookup Sales for EMP-130 | D64: =IF(C64="","[ Pending ]", IF(C64=The_Archive!B31, "✅ Correct", "❌ Try Again"))
B66: 31. Additional Task 31: Lookup Sales for EMP-131 | D66: =IF(C66="","[ Pending ]", IF(C66=The_Archive!B32, "✅ Correct", "❌ Try Again"))
B68: 32. Additional Task 32: Lookup Sales for EMP-132 | D68: =IF(C68="","[ Pending ]", IF(C68=The_Archive!B33, "✅ Correct", "❌ Try Again"))
B70: 33. Additional Task 33: Lookup Sales for EMP-133 | D70: =IF(C70="","[ Pending ]", IF(C70=The_Archive!B34, "✅ Correct", "❌ Try Again"))
B72: 34. Additional Task 34: Lookup Sales for EMP-134 | D72: =IF(C72="","[ Pending ]", IF(C72=The_Archive!B35, "✅ Correct", "❌ Try Again"))
B74: 35. Additional Task 35: Lookup Sales for EMP-135 | D74: =IF(C74="","[ Pending ]", IF(C74=The_Archive!B36, "✅ Correct", "❌ Try Again"))
B76: 36. Additional Task 36: Lookup Sales for EMP-136 | D76: =IF(C76="","[ Pending ]", IF(C76=The_Archive!B37, "✅ Correct", "❌ Try Again"))
B78: 37. Additional Task 37: Lookup Sales for EMP-137 | D78: =IF(C78="","[ Pending ]", IF(C78=The_Archive!B38, "✅ Correct", "❌ Try Again"))
B80: 38. Additional Task 38: Lookup Sales for EMP-138 | D80: =IF(C80="","[ Pending ]", IF(C80=The_Archive!B39, "✅ Correct", "❌ Try Again"))
B82: 39. Additional Task 39: Lookup Sales for EMP-139 | D82: =IF(C82="","[ Pending ]", IF(C82=The_Archive!B40, "✅ Correct", "❌ Try Again"))
...
