Workbook

Sheet Start Here
B12: Day 8: Data Validation & UI Architecture
B14: Build the User Interface of your spreadsheets. Control input, prevent errors, and master dependent logic.

Sheet UI_Source
A1: Category | B1: Item | C1: Status | D1: Priority
A2: Hardware | B2: Task 1 | C2: Published | D2: High
A3: SaaS | B3: Task 2 | C3: Draft | D3: Medium
A4: Consulting | B4: Task 3 | C4: Published | D4: Medium
A5: Hardware | B5: Task 4 | C5: Published | D5: Low
A6: Consulting | B6: Task 5 | C6: Draft | D6: Low
A7: Consulting | B7: Task 6 | C7: Published | D7: High
A8: SaaS | B8: Task 7 | C8: Review | D8: High
A9: Consulting | B9: Task 8 | C9: Review | D9: Medium
A10: SaaS | B10: Task 9 | C10: Published | D10: Medium
A11: Hardware | B11: Task 10 | C11: Published | D11: High
A12: SaaS | B12: Task 11 | C12: Draft | D12: Low
... A21: Hardware | B21: Task 20 | C21: Published | D21: Low

Sheet Lookup_Lists
A1: Tech | B1: Home | C1: Office
A2: Laptop | B2: Lamp | C2: Desk
A3: Mouse | B3: Chair | C3: Monitor
A4: Keyboard | B4: Desk | C4: Chair

Sheet The_Archive
A1: Task # | B1: Challenge | C1: Expected Formula / Method
A2: 1 | B2: Create a List Dropdown in Column C using values: SaaS, Hardware, Consulting | C2: SaaS
A3: 2 | B3: Create a Dropdown for 'Status' using the range UI_Source!$C$2:$C$10 | C3: Draft
A4: 3 | B4: Validate Column C to only allow Whole Numbers between 1 and 100 | C4: 50
A5: 4 | B5: Validate Column C to only allow Dates in the current year | C5: 1/1/2023
A6: 5 | B6: How do you add a custom 'Stop' Error Alert message? | C6: Error Alert
A7: 6 | B7: Dependent Dropdown: If B7 is 'Tech', C7 should show Tech items (using INDIRECT) | C7: Laptop
A8: 7 | B8: Dynamic Dropdown: Use the UNIQUE function results as a list (using # operator) | C8: UniqueList
A9: 8 | B9: Advanced UI Task 8: Control input for Cell C20 | C9: Value 8
A10: 9 | B10: Advanced UI Task 9: Control input for Cell C22 | C10: Value 9
A11: 10 | B11: Advanced UI Task 10: Control input for Cell C24 | C11: Value 10
A12: 11 | B12: Advanced UI Task 11: Control input for Cell C26 | C12: Value 11
A13: 12 | B13: Advanced UI Task 12: Control input for Cell C28 | C13: Value 12
... A41: 40 | B41: Advanced UI Task 40: Control input for Cell C84 | C41: Value 40

Sheet Mastery_Lab
B2: DATA VALIDATION & UI DRILL
B6: 1. Create a List Dropdown in Column C using values: SaaS, Hardware, Consulting | D6: =IF(C6="","[ Pending ]", IF(C6=The_Archive!C2, "✅ Correct", "❌ Try Again"))
B8: 2. Create a Dropdown for 'Status' using the range UI_Source!$C$2:$C$10 | D8: =IF(C8="","[ Pending ]", IF(C8=The_Archive!C3, "✅ Correct", "❌ Try Again"))
B10: 3. Validate Column C to only allow Whole Numbers between 1 and 100 | D10: =IF(C10="","[ Pending ]", IF(C10=The_Archive!C4, "✅ Correct", "❌ Try Again"))
B12: 4. Validate Column C to only allow Dates in the current year | D12: =IF(C12="","[ Pending ]", IF(C12=The_Archive!C5, "✅ Correct", "❌ Try Again"))
B14: 5. How do you add a custom 'Stop' Error Alert message? | D14: =IF(C14="","[ Pending ]", IF(C14=The_Archive!C6, "✅ Correct", "❌ Try Again"))
B16: 6. Dependent Dropdown: If B7 is 'Tech', C7 should show Tech items (using INDIRECT) | D16: =IF(C16="","[ Pending ]", IF(C16=The_Archive!C7, "✅ Correct", "❌ Try Again"))
B18: 7. Dynamic Dropdown: Use the UNIQUE function results as a list (using # operator) | D18: =IF(C18="","[ Pending ]", IF(C18=The_Archive!C8, "✅ Correct", "❌ Try Again"))
B20: 8. Advanced UI Task 8: Control input for Cell C20 | D20: =IF(C20="","[ Pending ]", IF(C20=The_Archive!C9, "✅ Correct", "❌ Try Again"))
B22: 9. Advanced UI Task 9: Control input for Cell C22 | D22: =IF(C22="","[ Pending ]", IF(C22=The_Archive!C10, "✅ Correct", "❌ Try Again"))
B24: 10. Advanced UI Task 10: Control input for Cell C24 | D24: =IF(C24="","[ Pending ]", IF(C24=The_Archive!C11, "✅ Correct", "❌ Try Again"))
B26: 11. Advanced UI Task 11: Control input for Cell C26 | D26: =IF(C26="","[ Pending ]", IF(C26=The_Archive!C12, "✅ Correct", "❌ Try Again"))
B28: 12. Advanced UI Task 12: Control input for Cell C28 | D28: =IF(C28="","[ Pending ]", IF(C28=The_Archive!C13, "✅ Correct", "❌ Try Again"))
B30: 13. Advanced UI Task 13: Control input for Cell C30 | D30: =IF(C30="","[ Pending ]", IF(C30=The_Archive!C14, "✅ Correct", "❌ Try Again"))
B32: 14. Advanced UI Task 14: Control input for Cell C32 | D32: =IF(C32="","[ Pending ]", IF(C32=The_Archive!C15, "✅ Correct", "❌ Try Again"))
B34: 15. Advanced UI Task 15: Control input for Cell C34 | D34: =IF(C34="","[ Pending ]", IF(C34=The_Archive!C16, "✅ Correct", "❌ Try Again"))
B36: 16. Advanced UI Task 16: Control input for Cell C36 | D36: =IF(C36="","[ Pending ]", IF(C36=The_Archive!C17, "✅ Correct", "❌ Try Again"))
B38: 17. Advanced UI Task 17: Control input for Cell C38 | D38: =IF(C38="","[ Pending ]", IF(C38=The_Archive!C18, "✅ Correct", "❌ Try Again"))
B40: 18. Advanced UI Task 18: Control input for Cell C40 | D40: =IF(C40="","[ Pending ]", IF(C40=The_Archive!C19, "✅ Correct", "❌ Try Again"))
B42: 19. Advanced UI Task 19: Control input for Cell C42 | D42: =IF(C42="","[ Pending ]", IF(C42=The_Archive!C20, "✅ Correct", "❌ Try Again"))
B44: 20. Advanced UI Task 20: Control input for Cell C44 | D44: =IF(C44="","[ Pending ]", IF(C44=The_Archive!C21, "✅ Correct", "❌ Try Again"))
B46: 21. Advanced UI Task 21: Control input for Cell C46 | D46: =IF(C46="","[ Pending ]", IF(C46=The_Archive!C22, "✅ Correct", "❌ Try Again"))
B48: 22. Advanced UI Task 22: Control input for Cell C48 | D48: =IF(C48="","[ Pending ]", IF(C48=The_Archive!C23, "✅ Correct", "❌ Try Again"))
B50: 23. Advanced UI Task 23: Control input for Cell C50 | D50: =IF(C50="","[ Pending ]", IF(C50=The_Archive!C24, "✅ Correct", "❌ Try Again"))
B52: 24. Advanced UI Task 24: Control input for Cell C52 | D52: =IF(C52="","[ Pending ]", IF(C52=The_Archive!C25, "✅ Correct", "❌ Try Again"))
B54: 25. Advanced UI Task 25: Control input for Cell C54 | D54: =IF(C54="","[ Pending ]", IF(C54=The_Archive!C26, "✅ Correct", "❌ Try Again"))
B56: 26. Advanced UI Task 26: Control input for Cell C56 | D56: =IF(C56="","[ Pending ]", IF(C56=The_Archive!C27, "✅ Correct", "❌ Try Again"))
B58: 27. Advanced UI Task 27: Control input for Cell C58 | D58: =IF(C58="","[ Pending ]", IF(C58=The_Archive!C28, "✅ Correct", "❌ Try Again"))
B60: 28. Advanced UI Task 28: Control input for Cell C60 | D60: =IF(C60="","[ Pending ]", IF(C60=The_Archive!C29, "✅ Correct", "❌ Try Again"))
B62: 29. Advanced UI Task 29: Control input for Cell C62 | D62: =IF(C62="","[ Pending ]", IF(C62=The_Archive!C30, "✅ Correct", "❌ Try Again"))
B64: 30. Advanced UI Task 30: Control input for Cell C64 | D64: =IF(C64="","[ Pending ]", IF(C64=The_Archive!C31, "✅ Correct", "❌ Try Again"))
B66: 31. Advanced UI Task 31: Control input for Cell C66 | D66: =IF(C66="","[ Pending ]", IF(C66=The_Archive!C32, "✅ Correct", "❌ Try Again"))
B68: 32. Advanced UI Task 32: Control input for Cell C68 | D68: =IF(C68="","[ Pending ]", IF(C68=The_Archive!C33, "✅ Correct", "❌ Try Again"))
B70: 33. Advanced UI Task 33: Control input for Cell C70 | D70: =IF(C70="","[ Pending ]", IF(C70=The_Archive!C34, "✅ Correct", "❌ Try Again"))
B72: 34. Advanced UI Task 34: Control input for Cell C72 | D72: =IF(C72="","[ Pending ]", IF(C72=The_Archive!C35, "✅ Correct", "❌ Try Again"))
B74: 35. Advanced UI Task 35: Control input for Cell C74 | D74: =IF(C74="","[ Pending ]", IF(C74=The_Archive!C36, "✅ Correct", "❌ Try Again"))
B76: 36. Advanced UI Task 36: Control input for Cell C76 | D76: =IF(C76="","[ Pending ]", IF(C76=The_Archive!C37, "✅ Correct", "❌ Try Again"))
B78: 37. Advanced UI Task 37: Control input for Cell C78 | D78: =IF(C78="","[ Pending ]", IF(C78=The_Archive!C38, "✅ Correct", "❌ Try Again"))
B80: 38. Advanced UI Task 38: Control input for Cell C80 | D80: =IF(C80="","[ Pending ]", IF(C80=The_Archive!C39, "✅ Correct", "❌ Try Again"))
B82: 39. Advanced UI Task 39: Control input for Cell C82 | D82: =IF(C82="","[ Pending ]", IF(C82=The_Archive!C40, "✅ Correct", "❌ Try Again"))
...
