Workbook

Sheet Start Here
B10: Day 5: Pivot Table Masterclass
B12: Summarize millions of rows in seconds. Build the foundations of a Data Architect's dashboard.

Sheet Sales_Data
A1: Order ID | B1: Date | C1: Category | D1: Amount | E1: Region
A2: ORD-5001 | B2: 2023-01-01 | C2: Cloud | D2: 1482 | E2: Global
A3: ORD-5002 | B3: 2023-01-01 | C3: Hardware | D3: 817 | E3: Global
A4: ORD-5003 | B4: 2023-01-01 | C4: Cloud | D4: 3059 | E4: LATAM
A5: ORD-5004 | B5: 2023-01-01 | C5: Cloud | D5: 4884 | E5: LATAM
A6: ORD-5005 | B6: 2023-01-01 | C6: Hardware | D6: 4972 | E6: Global
A7: ORD-5006 | B7: 2023-01-01 | C7: SaaS | D7: 3092 | E7: APAC
A8: ORD-5007 | B8: 2023-01-01 | C8: SaaS | D8: 280 | E8: Global
A9: ORD-5008 | B9: 2023-01-01 | C9: Consulting | D9: 3636 | E9: EMEA
A10: ORD-5009 | B10: 2023-01-01 | C10: Consulting | D10: 2729 | E10: EMEA
A11: ORD-5010 | B11: 2023-01-01 | C11: Cloud | D11: 4418 | E11: APAC
A12: ORD-5011 | B12: 2023-01-01 | C12: Cloud | D12: 241 | E12: EMEA
A13: ORD-5012 | B13: 2023-01-01 | C13: Hardware | D13: 2530 | E13: EMEA
... A201: ORD-5200 | B201: 2023-01-01 | C201: Cloud | D201: 627 | E201: Global

Sheet The_Archive
A1: Task # | B1: Expected Analysis Method
A2: 1 | B2: Right-click Date > Group > Months
A3: 2 | B3: Value Field Settings > Average
A4: 3 | B4: Filters Pane
A5: 4 | B5: Check Value
A6: 5 | B6: Check Value
A7: 6 | B7: Check Value
A8: 7 | B8: Check Value
A9: 8 | B9: Check Value
A10: 9 | B10: Check Value
A11: 10 | B11: Check Value
A12: 11 | B12: Check Value
A13: 12 | B13: Check Value
... A41: 40 | B41: Check Value

Sheet Mastery_Lab
B2: PIVOT TABLE ANALYTICS DRILL
B6: 1. How do you group dates by Month in a Pivot Table? | D6: =IF(C6="","[ Pending ]", IF(C6=The_Archive!B2, "✅ Correct", "❌ Try Again"))
B8: 2. How do you change Sum of Amount to Average of Amount? | D8: =IF(C8="","[ Pending ]", IF(C8=The_Archive!B3, "✅ Correct", "❌ Try Again"))
B10: 3. Which pane do you use to filter the entire Pivot Table? | D10: =IF(C10="","[ Pending ]", IF(C10=The_Archive!B4, "✅ Correct", "❌ Try Again"))
B12: 4. Additional Task 4: Analytical question regarding order 5004 | D12: =IF(C12="","[ Pending ]", IF(C12=The_Archive!B5, "✅ Correct", "❌ Try Again"))
B14: 5. Additional Task 5: Analytical question regarding order 5005 | D14: =IF(C14="","[ Pending ]", IF(C14=The_Archive!B6, "✅ Correct", "❌ Try Again"))
B16: 6. Additional Task 6: Analytical question regarding order 5006 | D16: =IF(C16="","[ Pending ]", IF(C16=The_Archive!B7, "✅ Correct", "❌ Try Again"))
B18: 7. Additional Task 7: Analytical question regarding order 5007 | D18: =IF(C18="","[ Pending ]", IF(C18=The_Archive!B8, "✅ Correct", "❌ Try Again"))
B20: 8. Additional Task 8: Analytical question regarding order 5008 | D20: =IF(C20="","[ Pending ]", IF(C20=The_Archive!B9, "✅ Correct", "❌ Try Again"))
B22: 9. Additional Task 9: Analytical question regarding order 5009 | D22: =IF(C22="","[ Pending ]", IF(C22=The_Archive!B10, "✅ Correct", "❌ Try Again"))
B24: 10. Additional Task 10: Analytical question regarding order 5010 | D24: =IF(C24="","[ Pending ]", IF(C24=The_Archive!B11, "✅ Correct", "❌ Try Again"))
B26: 11. Additional Task 11: Analytical question regarding order 5011 | D26: =IF(C26="","[ Pending ]", IF(C26=The_Archive!B12, "✅ Correct", "❌ Try Again"))
B28: 12. Additional Task 12: Analytical question regarding order 5012 | D28: =IF(C28="","[ Pending ]", IF(C28=The_Archive!B13, "✅ Correct", "❌ Try Again"))
B30: 13. Additional Task 13: Analytical question regarding order 5013 | D30: =IF(C30="","[ Pending ]", IF(C30=The_Archive!B14, "✅ Correct", "❌ Try Again"))
B32: 14. Additional Task 14: Analytical question regarding order 5014 | D32: =IF(C32="","[ Pending ]", IF(C32=The_Archive!B15, "✅ Correct", "❌ Try Again"))
B34: 15. Additional Task 15: Analytical question regarding order 5015 | D34: =IF(C34="","[ Pending ]", IF(C34=The_Archive!B16, "✅ Correct", "❌ Try Again"))
B36: 16. Additional Task 16: Analytical question regarding order 5016 | D36: =IF(C36="","[ Pending ]", IF(C36=The_Archive!B17, "✅ Correct", "❌ Try Again"))
B38: 17. Additional Task 17: Analytical question regarding order 5017 | D38: =IF(C38="","[ Pending ]", IF(C38=The_Archive!B18, "✅ Correct", "❌ Try Again"))
B40: 18. Additional Task 18: Analytical question regarding order 5018 | D40: =IF(C40="","[ Pending ]", IF(C40=The_Archive!B19, "✅ Correct", "❌ Try Again"))
B42: 19. Additional Task 19: Analytical question regarding order 5019 | D42: =IF(C42="","[ Pending ]", IF(C42=The_Archive!B20, "✅ Correct", "❌ Try Again"))
B44: 20. Additional Task 20: Analytical question regarding order 5020 | D44: =IF(C44="","[ Pending ]", IF(C44=The_Archive!B21, "✅ Correct", "❌ Try Again"))
B46: 21. Additional Task 21: Analytical question regarding order 5021 | D46: =IF(C46="","[ Pending ]", IF(C46=The_Archive!B22, "✅ Correct", "❌ Try Again"))
B48: 22. Additional Task 22: Analytical question regarding order 5022 | D48: =IF(C48="","[ Pending ]", IF(C48=The_Archive!B23, "✅ Correct", "❌ Try Again"))
B50: 23. Additional Task 23: Analytical question regarding order 5023 | D50: =IF(C50="","[ Pending ]", IF(C50=The_Archive!B24, "✅ Correct", "❌ Try Again"))
B52: 24. Additional Task 24: Analytical question regarding order 5024 | D52: =IF(C52="","[ Pending ]", IF(C52=The_Archive!B25, "✅ Correct", "❌ Try Again"))
B54: 25. Additional Task 25: Analytical question regarding order 5025 | D54: =IF(C54="","[ Pending ]", IF(C54=The_Archive!B26, "✅ Correct", "❌ Try Again"))
B56: 26. Additional Task 26: Analytical question regarding order 5026 | D56: =IF(C56="","[ Pending ]", IF(C56=The_Archive!B27, "✅ Correct", "❌ Try Again"))
B58: 27. Additional Task 27: Analytical question regarding order 5027 | D58: =IF(C58="","[ Pending ]", IF(C58=The_Archive!B28, "✅ Correct", "❌ Try Again"))
B60: 28. Additional Task 28: Analytical question regarding order 5028 | D60: =IF(C60="","[ Pending ]", IF(C60=The_Archive!B29, "✅ Correct", "❌ Try Again"))
B62: 29. Additional Task 29: Analytical question regarding order 5029 | D62: =IF(C62="","[ Pending ]", IF(C62=The_Archive!B30, "✅ Correct", "❌ Try Again"))
B64: 30. Additional Task 30: Analytical question regarding order 5030 | D64: =IF(C64="","[ Pending ]", IF(C64=The_Archive!B31, "✅ Correct", "❌ Try Again"))
B66: 31. Additional Task 31: Analytical question regarding order 5031 | D66: =IF(C66="","[ Pending ]", IF(C66=The_Archive!B32, "✅ Correct", "❌ Try Again"))
B68: 32. Additional Task 32: Analytical question regarding order 5032 | D68: =IF(C68="","[ Pending ]", IF(C68=The_Archive!B33, "✅ Correct", "❌ Try Again"))
B70: 33. Additional Task 33: Analytical question regarding order 5033 | D70: =IF(C70="","[ Pending ]", IF(C70=The_Archive!B34, "✅ Correct", "❌ Try Again"))
B72: 34. Additional Task 34: Analytical question regarding order 5034 | D72: =IF(C72="","[ Pending ]", IF(C72=The_Archive!B35, "✅ Correct", "❌ Try Again"))
B74: 35. Additional Task 35: Analytical question regarding order 5035 | D74: =IF(C74="","[ Pending ]", IF(C74=The_Archive!B36, "✅ Correct", "❌ Try Again"))
B76: 36. Additional Task 36: Analytical question regarding order 5036 | D76: =IF(C76="","[ Pending ]", IF(C76=The_Archive!B37, "✅ Correct", "❌ Try Again"))
B78: 37. Additional Task 37: Analytical question regarding order 5037 | D78: =IF(C78="","[ Pending ]", IF(C78=The_Archive!B38, "✅ Correct", "❌ Try Again"))
B80: 38. Additional Task 38: Analytical question regarding order 5038 | D80: =IF(C80="","[ Pending ]", IF(C80=The_Archive!B39, "✅ Correct", "❌ Try Again"))
B82: 39. Additional Task 39: Analytical question regarding order 5039 | D82: =IF(C82="","[ Pending ]", IF(C82=The_Archive!B40, "✅ Correct", "❌ Try Again"))
...
